Workbook

Sheet Final_evaluation
A1: instance | B1: crash_detection_gemini_code | C1: crash_detection_gemini_runinfo | D1: crash_detection_qwen_code | E1: crash_detection_qwen_runinfo | F1: crash_detection_gpt5_code | G1: crash_detection_gpt5_runinfo
A2: tensorflow_1_fixed | B2: correct | C2: correct | D2: correct | E2: correct | F2: correct | G2: correct
A3: tensorflow_2_fixed | B3: correct | C3: wrong | D3: correct | E3: correct | F3: correct | G3: correct
A4: tensorflow_3_fixed | B4: correct | C4: correct | D4: correct | E4: correct | F4: correct | G4: correct
A5: tensorflow_4_fixed | B5: wrong | C5: wrong | D5: correct | E5: correct | F5: wrong | G5: wrong
A6: tensorflow_5_fixed | B6: wrong | C6: wrong | D6: correct | E6: correct | F6: correct | G6: correct
A7: tensorflow_6_fixed | B7: wrong | C7: wrong | D7: wrong | E7: correct | F7: correct | G7: correct
A8: tensorflow_7_fixed | B8: correct | C8: wrong | D8: wrong | E8: correct | F8: correct | G8: correct
A9: tensorflow_8_fixed | B9: wrong | C9: wrong | D9: correct | E9: correct | F9: correct | G9: correct
A10: tensorflow_9_fixed | B10: wrong | C10: correct | D10: wrong | E10: correct | F10: correct | G10: correct
A11: tensorflow_10_fixed | B11: wrong | C11: wrong | D11: wrong | E11: correct | F11: correct | G11: correct
A12: tensorflow_11_fixed | B12: wrong | C12: wrong | D12: correct | E12: correct | F12: correct | G12: correct
... A223: NBspecific_20_reproduced | B223: correct | C223: correct | D223: correct | E223: correct | F223: correct | G223: correct
A224: FP_tensorflow | B224: {=SUM(COUNTIF(Final_evaluation!$B$2:'Final_evaluation'!$B$16, {"<>correct"}))} -> 9 | C224: {=SUM(COUNTIF(Final_evaluation!$C$2:'Final_evaluation'!$C$16, {"<>correct"}))} -> 11 | D224: {=SUM(COUNTIF(Final_evaluation!$D$2:'Final_evaluation'!$D$16, {"<>correct"}))} -> 5 | E224: {=SUM(COUNTIF(Final_evaluation!$E$2:'Final_evaluation'!$E$16, {"<>correct"}))} -> 0 | F224: {=SUM(COUNTIF(Final_evaluation!$F$2:'Final_evaluation'!$F$16, {"<>correct"}))} -> 3 | G224: {=SUM(COUNTIF(Final_evaluation!$G$2:'Final_evaluation'!$G$16, {"<>correct"}))} -> 2
A225: FN_tensorflow | B225: {=SUM(COUNTIF(Final_evaluation!$B$17:'Final_evaluation'!$B$31, {"<>correct"}))} -> 3 | C225: {=SUM(COUNTIF(Final_evaluation!$C$17:'Final_evaluation'!$C$31, {"<>correct"}))} -> 2 | D225: {=SUM(COUNTIF(Final_evaluation!$D$17:'Final_evaluation'!$D$31, {"<>correct"}))} -> 3 | E225: {=SUM(COUNTIF(Final_evaluation!$E$17:'Final_evaluation'!$E$31, {"<>correct"}))} -> 3 | F225: {=SUM(COUNTIF(Final_evaluation!$F$17:'Final_evaluation'!$F$31, {"<>correct"}))} -> 4 | G225: {=SUM(COUNTIF(Final_evaluation!$G$17:'Final_evaluation'!$G$31, {"<>correct"}))} -> 3
A226: FP_torch | B226: {=SUM(COUNTIF(Final_evaluation!$B$32:'Final_evaluation'!$B$46, {"<>correct"}))} -> 10 | C226: {=SUM(COUNTIF(Final_evaluation!$C$32:'Final_evaluation'!$C$46, {"<>correct"}))} -> 10 | D226: {=SUM(COUNTIF(Final_evaluation!$D$32:'Final_evaluation'!$D$46, {"<>correct"}))} -> 5 | E226: {=SUM(COUNTIF(Final_evaluation!$E$32:'Final_evaluation'!$E$46, {"<>correct"}))} -> 5 | F226: {=SUM(COUNTIF(Final_evaluation!$F$32:'Final_evaluation'!$F$46, {"<>correct"}))} -> 3 | G226: {=SUM(COUNTIF(Final_evaluation!$G$32:'Final_evaluation'!$G$46, {"<>correct"}))} -> 5
A227: FN_torch | B227: {=SUM(COUNTIF(Final_evaluation!$B$47:'Final_evaluation'!$B$61, {"<>correct"}))} -> 10 | C227: {=SUM(COUNTIF(Final_evaluation!$C$47:'Final_evaluation'!$C$61, {"<>correct"}))} -> 9 | D227: {=SUM(COUNTIF(Final_evaluation!$D$47:'Final_evaluation'!$D$61, {"<>correct"}))} -> 14 | E227: {=SUM(COUNTIF(Final_evaluation!$E$47:'Final_evaluation'!$E$61, {"<>correct"}))} -> 12 | F227: {=SUM(COUNTIF(Final_evaluation!$F$47:'Final_evaluation'!$F$61, {"<>correct"}))} -> 11 | G227: {=SUM(COUNTIF(Final_evaluation!$G$47:'Final_evaluation'!$G$61, {"<>correct"}))} -> 6
A228: FP_sklearn | B228: {=SUM(COUNTIF(Final_evaluation!$B$62:'Final_evaluation'!$B$76, {"<>correct"}))} -> 5 | C228: {=SUM(COUNTIF(Final_evaluation!$C$62:'Final_evaluation'!$C$76, {"<>correct"}))} -> 4 | D228: {=SUM(COUNTIF(Final_evaluation!$D$62:'Final_evaluation'!$D$76, {"<>correct"}))} -> 2 | E228: {=SUM(COUNTIF(Final_evaluation!$E$62:'Final_evaluation'!$E$76, {"<>correct"}))} -> 1 | F228: {=SUM(COUNTIF(Final_evaluation!$F$62:'Final_evaluation'!$F$76, {"<>correct"}))} -> 2 | G228: {=SUM(COUNTIF(Final_evaluation!$G$62:'Final_evaluation'!$G$76, {"<>correct"}))} -> 3
A229: FN_sklearn | B229: {=SUM(COUNTIF(Final_evaluation!$B$77:'Final_evaluation'!$B$91, {"<>correct"}))} -> 7 | C229: {=SUM(COUNTIF(Final_evaluation!$C$77:'Final_evaluation'!$C$91, {"<>correct"}))} -> 2 | D229: {=SUM(COUNTIF(Final_evaluation!$D$77:'Final_evaluation'!$D$91, {"<>correct"}))} -> 8 | E229: {=SUM(COUNTIF(Final_evaluation!$E$77:'Final_evaluation'!$E$91, {"<>correct"}))} -> 5 | F229: {=SUM(COUNTIF(Final_evaluation!$F$77:'Final_evaluation'!$F$91, {"<>correct"}))} -> 4 | G229: {=SUM(COUNTIF(Final_evaluation!$G$77:'Final_evaluation'!$G$91, {"<>correct"}))} -> 1
A230: FP_pandas | B230: {=SUM(COUNTIF(Final_evaluation!$B$92:'Final_evaluation'!$B$106, {"<>correct"}))} -> 7 | C230: {=SUM(COUNTIF(Final_evaluation!$C$92:'Final_evaluation'!$C$106, {"<>correct"}))} -> 3 | D230: {=SUM(COUNTIF(Final_evaluation!$D$92:'Final_evaluation'!$D$106, {"<>correct"}))} -> 5 | E230: {=SUM(COUNTIF(Final_evaluation!$E$92:'Final_evaluation'!$E$106, {"<>correct"}))} -> 2 | F230: {=SUM(COUNTIF(Final_evaluation!$F$92:'Final_evaluation'!$F$106, {"<>correct"}))} -> 5 | G230: {=SUM(COUNTIF(Final_evaluation!$G$92:'Final_evaluation'!$G$106, {"<>correct"}))} -> 2
A231: FN_pandas | B231: {=SUM(COUNTIF(Final_evaluation!$B$107:'Final_evaluation'!$B$121, {"<>correct"}))} -> 5 | C231: {=SUM(COUNTIF(Final_evaluation!$C$107:'Final_evaluation'!$C$121, {"<>correct"}))} -> 3 | D231: {=SUM(COUNTIF(Final_evaluation!$D$107:'Final_evaluation'!$D$121, {"<>correct"}))} -> 7 | E231: {=SUM(COUNTIF(Final_evaluation!$E$107:'Final_evaluation'!$E$121, {"<>correct"}))} -> 6 | F231: {=SUM(COUNTIF(Final_evaluation!$F$107:'Final_evaluation'!$F$121, {"<>correct"}))} -> 11 | G231: {=SUM(COUNTIF(Final_evaluation!$G$107:'Final_evaluation'!$G$121, {"<>correct"}))} -> 8
A232: FP_numpy | B232: {=SUM(COUNTIF(Final_evaluation!$B$122:'Final_evaluation'!$B$136, {"<>correct"}))} -> 7 | C232: {=SUM(COUNTIF(Final_evaluation!$C$122:'Final_evaluation'!$C$136, {"<>correct"}))} -> 10 | D232: {=SUM(COUNTIF(Final_evaluation!$D$122:'Final_evaluation'!$D$136, {"<>correct"}))} -> 5 | E232: {=SUM(COUNTIF(Final_evaluation!$E$122:'Final_evaluation'!$E$136, {"<>correct"}))} -> 2 | F232: {=SUM(COUNTIF(Final_evaluation!$F$122:'Final_evaluation'!$F$136, {"<>correct"}))} -> 4 | G232: {=SUM(COUNTIF(Final_evaluation!$G$122:'Final_evaluation'!$G$136, {"<>correct"}))} -> 3
A233: FN_numpy | B233: {=SUM(COUNTIF(Final_evaluation!$B$137:'Final_evaluation'!$B$151, {"<>correct"}))} -> 9 | C233: {=SUM(COUNTIF(Final_evaluation!$C$137:'Final_evaluation'!$C$151, {"<>correct"}))} -> 8 | D233: {=SUM(COUNTIF(Final_evaluation!$D$137:'Final_evaluation'!$D$151, {"<>correct"}))} -> 12 | E233: {=SUM(COUNTIF(Final_evaluation!$E$137:'Final_evaluation'!$E$151, {"<>correct"}))} -> 11 | F233: {=SUM(COUNTIF(Final_evaluation!$F$137:'Final_evaluation'!$F$151, {"<>correct"}))} -> 6 | G233: {=SUM(COUNTIF(Final_evaluation!$G$137:'Final_evaluation'!$G$151, {"<>correct"}))} -> 7
A234: FP_other | B234: {=SUM(COUNTIF(Final_evaluation!$B$152:'Final_evaluation'!$B$167, {"<>correct"}))} -> 7 | C234: {=SUM(COUNTIF(Final_evaluation!$C$152:'Final_evaluation'!$C$167, {"<>correct"}))} -> 6 | D234: {=SUM(COUNTIF(Final_evaluation!$D$152:'Final_evaluation'!$D$167, {"<>correct"}))} -> 4 | E234: {=SUM(COUNTIF(Final_evaluation!$E$152:'Final_evaluation'!$E$167, {"<>correct"}))} -> 2 | F234: {=SUM(COUNTIF(Final_evaluation!$F$152:'Final_evaluation'!$F$167, {"<>correct"}))} -> 3 | G234: {=SUM(COUNTIF(Final_evaluation!$G$152:'Final_evaluation'!$G$167, {"<>correct"}))} -> 4
A235: FN_other | B235: {=SUM(COUNTIF(Final_evaluation!$B$168:'Final_evaluation'!$B$183, {"<>correct"}))} -> 8 | C235: {=SUM(COUNTIF(Final_evaluation!$C$168:'Final_evaluation'!$C$183, {"<>correct"}))} -> 6 | D235: {=SUM(COUNTIF(Final_evaluation!$D$168:'Final_evaluation'!$D$183, {"<>correct"}))} -> 11 | E235: {=SUM(COUNTIF(Final_evaluation!$E$168:'Final_evaluation'!$E$183, {"<>correct"}))} -> 10 | F235: {=SUM(COUNTIF(Final_evaluation!$F$168:'Final_evaluation'!$F$183, {"<>correct"}))} -> 9 | G235: {=SUM(COUNTIF(Final_evaluation!$G$168:'Final_evaluation'!$G$183, {"<>correct"}))} -> 6
A236: FP_NBspecific | B236: {=SUM(COUNTIF(Final_evaluation!$B$184:'Final_evaluation'!$B$203, {"<>correct"}))} -> 6 | C236: {=SUM(COUNTIF(Final_evaluation!$C$184:'Final_evaluation'!$C$203, {"<>correct"}))} -> 3 | D236: {=SUM(COUNTIF(Final_evaluation!$D$184:'Final_evaluation'!$D$203, {"<>correct"}))} -> 1 | E236: {=SUM(COUNTIF(Final_evaluation!$E$184:'Final_evaluation'!$E$203, {"<>correct"}))} -> 0 | F236: {=SUM(COUNTIF(Final_evaluation!$F$184:'Final_evaluation'!$F$203, {"<>correct"}))} -> 1 | G236: {=SUM(COUNTIF(Final_evaluation!$G$184:'Final_evaluation'!$G$203, {"<>correct"}))} -> 1
A237: FN_NBspecific | B237: {=SUM(COUNTIF(Final_evaluation!$B$204:'Final_evaluation'!$B$223, {"<>correct"}))} -> 0 | C237: {=SUM(COUNTIF(Final_evaluation!$C$204:'Final_evaluation'!$C$223, {"<>correct"}))} -> 0 | D237: {=SUM(COUNTIF(Final_evaluation!$D$204:'Final_evaluation'!$D$223, {"<>correct"}))} -> 0 | E237: {=SUM(COUNTIF(Final_evaluation!$E$204:'Final_evaluation'!$E$223, {"<>correct"}))} -> 2 | F237: {=SUM(COUNTIF(Final_evaluation!$F$204:'Final_evaluation'!$F$223, {"<>correct"}))} -> 3 | G237: {=SUM(COUNTIF(Final_evaluation!$G$204:'Final_evaluation'!$G$223, {"<>correct"}))} -> 1
A238: corrects_tensorflow | B238: {=SUM(COUNTIF($B$2:$B$31, {"correct"}))} -> 18 | C238: {=SUM(COUNTIF($C$2:$C$31, {"correct"}))} -> 17 | D238: {=SUM(COUNTIF($D$2:$D$31, {"correct"}))} -> 22 | E238: {=SUM(COUNTIF($E$2:$E$31, {"correct"}))} -> 27 | F238: {=SUM(COUNTIF($F$2:$F$31, {"correct"}))} -> 23 | G238: {=SUM(COUNTIF($G$2:$G$31, {"correct"}))} -> 25
A239: acc_tensorflow | B239: =B238/ COUNTA($B$2:$B$31) -> 0.6 | C239: =C238/ COUNTA($C$2:$C$31) -> 0.56666667 | D239: =D238/ COUNTA($D$2:$D$31) -> 0.73333333 | E239: =E238/ COUNTA($E$2:$E$31) -> 0.9 | F239: =F238/ COUNTA($F$2:$F$31) -> 0.76666667 | G239: =G238/ COUNTA($G$2:$G$31) -> 0.83333333
A240: corrects_torch | B240: {=SUM(COUNTIF($B$32:$B$61, {"correct"}))} -> 10 | C240: {=SUM(COUNTIF($C$32:$C$61, {"correct"}))} -> 11 | D240: {=SUM(COUNTIF($D$32:$D$61, {"correct"}))} -> 11 | E240: {=SUM(COUNTIF($E$32:$E$61, {"correct"}))} -> 13 | F240: {=SUM(COUNTIF($F$32:$F$61, {"correct"}))} -> 16 | G240: {=SUM(COUNTIF($G$32:$G$61, {"correct"}))} -> 19
A241: acc_torch | B241: =B240/ COUNTA($B$32:$B$61) -> 0.33333333 | C241: =C240/ COUNTA($C$32:$C$61) -> 0.36666667 | D241: =D240/ COUNTA($D$32:$D$61) -> 0.36666667 | E241: =E240/ COUNTA($E$32:$E$61) -> 0.43333333 | F241: =F240/ COUNTA($F$32:$F$61) -> 0.53333333 | G241: =G240/ COUNTA($G$32:$G$61) -> 0.63333333
A242: corrects_sklearn | B242: {=SUM(COUNTIF($B$62:$B$91, {"correct"}))} -> 18 | C242: {=SUM(COUNTIF($C$62:$C$91, {"correct"}))} -> 24 | D242: {=SUM(COUNTIF($D$62:$D$91, {"correct"}))} -> 20 | E242: {=SUM(COUNTIF($E$62:$E$91, {"correct"}))} -> 24 | F242: {=SUM(COUNTIF($F$62:$F$91, {"correct"}))} -> 24 | G242: {=SUM(COUNTIF($G$62:$G$91, {"correct"}))} -> 26
A243: acc_sklearn | B243: =B242/ COUNTA($B$62:$B$91) -> 0.6 | C243: =C242/ COUNTA($C$62:$C$91) -> 0.8 | D243: =D242/ COUNTA($D$62:$D$91) -> 0.66666667 | E243: =E242/ COUNTA($E$62:$E$91) -> 0.8 | F243: =F242/ COUNTA($F$62:$F$91) -> 0.8 | G243: =G242/ COUNTA($G$62:$G$91) -> 0.86666667
A244: corrects_pandas | B244: {=SUM(COUNTIF($B$92:$B$121, {"correct"}))} -> 18 | C244: {=SUM(COUNTIF($C$92:$C$121, {"correct"}))} -> 24 | D244: {=SUM(COUNTIF($D$92:$D$121, {"correct"}))} -> 18 | E244: {=SUM(COUNTIF($E$92:$E$121, {"correct"}))} -> 22 | F244: {=SUM(COUNTIF($F$92:$F$121, {"correct"}))} -> 14 | G244: {=SUM(COUNTIF($G$92:$G$121, {"correct"}))} -> 20
A245: acc_pandas | B245: =B244/ COUNTA( $B$92:$B$121) -> 0.6 | C245: =C244/ COUNTA( $C$92:$C$121) -> 0.8 | D245: =D244/ COUNTA( $D$92:$D$121) -> 0.6 | E245: =E244/ COUNTA( $E$92:$E$121) -> 0.73333333 | F245: =F244/ COUNTA( $F$92:$F$121) -> 0.46666667 | G245: =G244/ COUNTA( $G$92:$G$121) -> 0.66666667
A246: corrects_numpy | B246: {=SUM(COUNTIF($B$122:$B$151, {"correct"}))} -> 14 | C246: {=SUM(COUNTIF($C$122:$C$151, {"correct"}))} -> 12 | D246: {=SUM(COUNTIF($D$122:$D$151, {"correct"}))} -> 13 | E246: {=SUM(COUNTIF($E$122:$E$151, {"correct"}))} -> 17 | F246: {=SUM(COUNTIF($F$122:$F$151, {"correct"}))} -> 20 | G246: {=SUM(COUNTIF($G$122:$G$151, {"correct"}))} -> 20
A247: acc_numpy | B247: =B246/ COUNTA( $B$122:$B$151) -> 0.46666667 | C247: =C246/ COUNTA( $C$122:$C$151) -> 0.4 | D247: =D246/ COUNTA( $D$122:$D$151) -> 0.43333333 | E247: =E246/ COUNTA( $E$122:$E$151) -> 0.56666667 | F247: =F246/ COUNTA( $F$122:$F$151) -> 0.66666667 | G247: =G246/ COUNTA( $G$122:$G$151) -> 0.66666667
A248: corrects_other | B248: {=SUM(COUNTIF($B$152:$B$183, {"correct"}))} -> 17 | C248: {=SUM(COUNTIF($C$152:$C$183, {"correct"}))} -> 20 | D248: {=SUM(COUNTIF($D$152:$D$183, {"correct"}))} -> 17 | E248: {=SUM(COUNTIF($E$152:$E$183, {"correct"}))} -> 20 | F248: {=SUM(COUNTIF($F$152:$F$183, {"correct"}))} -> 20 | G248: {=SUM(COUNTIF($G$152:$G$183, {"correct"}))} -> 22
A249: acc_other | B249: =B248/ COUNTA( $B$152:$B$183) -> 0.53125 | C249: =C248/ COUNTA( $C$152:$C$183) -> 0.625 | D249: =D248/ COUNTA( $D$152:$D$183) -> 0.53125 | E249: =E248/ COUNTA( $E$152:$E$183) -> 0.625 | F249: =F248/ COUNTA( $F$152:$F$183) -> 0.625 | G249: =G248/ COUNTA( $G$152:$G$183) -> 0.6875
A250: corrects_nbspecific | B250: {=SUM(COUNTIF($B$184:$B$223, {"correct"}))} -> 34 | C250: {=SUM(COUNTIF($C$184:$C$223, {"correct"}))} -> 37 | D250: {=SUM(COUNTIF($D$184:$D$223, {"correct"}))} -> 39 | E250: {=SUM(COUNTIF($E$184:$E$223, {"correct"}))} -> 38 | F250: {=SUM(COUNTIF($F$184:$F$223, {"correct"}))} -> 36 | G250: {=SUM(COUNTIF($G$184:$G$223, {"correct"}))} -> 38
...

Sheet Results_summary
A1: Crash detection and diagnosis results | T1: Overall results
T2: LLM | U2: Crash detection and diagnosis
A3: gemini 2.5 flash | B3: Count | C3: FP-RT | D3: FP+RT | E3: FN-RT | F3: FN+RT | G3: FPR-RT | H3: FPR+RT | I3: FNR-RT | J3: FNR+RT | K3: Prec-RT | L3: Prec+RT | M3: Rec-RT | N3: Rec+RT | O3: F1-RT | P3: F1+RT | Q3: Acc-RT | R3: Acc+RT | U3: Prec-RT | V3: Prec+RT | W3: Rec-RT | X3: Rec+RT | Y3: F1-RT | Z3: F1+RT | AA3: Acc-RT | AB3: Acc+RT
A4: tensorflow | B4: 30 | C4: =Final_evaluation!$B$224 -> 9 | D4: =Final_evaluation!$C$224 -> 11 | E4: =Final_evaluation!$B$225 -> 3 | F4: =Final_evaluation!$C$225 -> 2 | G4: =C4/B4 -> 0.3 | H4: =D4/B4 -> 0.36666667 | I4: =E4/B4 -> 0.1 | J4: =F4/B4 -> 0.066666667 | K4: =($B$4/2-$E$4)/(($B$4/2-$E$4)+$C$4) -> 0.57142857 | L4: =($B$4/2-$F$4)/(($B$4/2-$F$4)+$D$4) -> 0.54166667 | M4: =($B$4/2-$E$4)/($B$4/2) -> 0.8 | N4: =($B$4/2-$F$4)/($B$4/2) -> 0.86666667 | O4: =$K$4*$M$4*2/($K$4+$M$4) -> 0.66666667 | P4: =$L$4*$N$4*2/($L$4+$N$4) -> 0.66666667 | Q4: =($B$4-$C$4-$E$4)/$B$4 -> 0.6 | R4: =($B$4-$D$4-$F$4)/$B$4 -> 0.56666667 | T4: LLM - gemini | U4: =($B$11/2-$E$11)/(($B$11/2-$E$11)+$C$11) -> 0.575 | V4: =($B$11/2-$F$11)/(($B$11/2-$F$11)+$D$11) -> 0.6328125 | W4: =($B$11/2-$E$11)/($B$11/2) -> 0.62162162 | X4: =($B$11/2-$F$11)/($B$11/2) -> 0.72972973 | Y4: =$K$11*$M$11*2/($K$11+$M$11) -> 0.5974026 | Z4: =$L$11*$N$11*2/($L$11+$N$11) -> 0.67782427 | AA4: =($B$11-$C$11-$E$11)/$B$11 -> 0.58108108 | AB4: =($B$11-$D$11-$F$11)/$B$11 -> 0.65315315
A5: torch | B5: 30 | C5: =Final_evaluation!$B$226 -> 10 | D5: =Final_evaluation!$C$226 -> 10 | E5: =Final_evaluation!$B$227 -> 10 | F5: =Final_evaluation!$C$227 -> 9 | G5: =C5/B5 -> 0.33333333 | H5: =D5/B5 -> 0.33333333 | I5: =E5/B5 -> 0.33333333 | J5: =F5/B5 -> 0.3 | K5: =($B$5/2-$E$5)/(($B$5/2-$E$5)+$C$5) -> 0.33333333 | L5: =($B$5/2-$F$5)/(($B$5/2-$F$5)+$D$5) -> 0.375 | M5: =($B$5/2-$E$5)/($B$5/2) -> 0.33333333 | N5: =($B$5/2-$F$5)/($B$5/2) -> 0.4 | O5: =$K$5*$M$5*2/($K$5+$M$5) -> 0.33333333 | P5: =$L$5*$N$5*2/($L$5+$N$5) -> 0.38709677 | Q5: =($B$5-$C$5-$E$5)/$B$5 -> 0.33333333 | R5: =($B$5-$D$5-$F$5)/$B$5 -> 0.36666667 | T5: LLM - qwen | U5: =($B$22/2-$E$22)/(($B$22/2-$E$22)+$C$22) -> 0.6746988 | V5: =($B$22/2-$F$22)/(($B$22/2-$F$22)+$D$22) -> 0.83783784 | W5: =($B$22/2-$E$22)/($B$22/2) -> 0.5045045 | X5: =($B$22/2-$F$22)/($B$22/2) -> 0.55855856 | Y5: =$K$22*$M$22*2/($K$22+$M$22) -> 0.57731959 | Z5: =$L$22*$N$22*2/($L$22+$N$22) -> 0.67027027 | AA5: =($B$22-$C$22-$E$22)/$B$22 -> 0.63063063 | AB5: =($B$22-$D$22-$F$22)/$B$22 -> 0.72522523
A6: sklearn | B6: 30 | C6: =Final_evaluation!$B$228 -> 5 | D6: =Final_evaluation!$C$228 -> 4 | E6: =Final_evaluation!$B$229 -> 7 | F6: =Final_evaluation!$C$229 -> 2 | G6: =C6/B6 -> 0.16666667 | H6: =D6/B6 -> 0.13333333 | I6: =E6/B6 -> 0.23333333 | J6: =F6/B6 -> 0.066666667 | K6: =($B$6/2-$E$6)/(($B$6/2-$E$6)+$C$6) -> 0.61538462 | L6: =($B$6/2-$F$6)/(($B$6/2-$F$6)+$D$6) -> 0.76470588 | M6: =($B$6/2-$E$6)/($B$6/2) -> 0.53333333 | N6: =($B$6/2-$F$6)/($B$6/2) -> 0.86666667 | O6: =$K$6*$M$6*2/($K$6+$M$6) -> 0.57142857 | P6: =$L$6*$N$6*2/($L$6+$N$6) -> 0.8125 | Q6: =($B$6-$C$6-$E$6)/$B$6 -> 0.6 | R6: =($B$6-$D$6-$F$6)/$B$6 -> 0.8 | T6: LLM - gpt5 | U6: =($B$33/2-$E$33)/(($B$33/2-$E$33)+$C$33) -> 0.75 | V6: =($B$33/2-$F$33)/(($B$33/2-$F$33)+$D$33) -> 0.7979798 | W6: =($B$33/2-$E$33)/($B$33/2) -> 0.56756757 | X6: =($B$33/2-$F$33)/($B$33/2) -> 0.71171171 | Y6: =$K$33*$M$33*2/($K$33+$M$33) -> 0.64615385 | Z6: =$L$33*$N$33*2/($L$33+$N$33) -> 0.75238095 | AA6: =($B$33-$C$33-$E$33)/$B$33 -> 0.68918919 | AB6: =($B$33-$D$33-$F$33)/$B$33 -> 0.76576577
A7: pandas | B7: 30 | C7: =Final_evaluation!$B$230 -> 7 | D7: =Final_evaluation!$C$230 -> 3 | E7: =Final_evaluation!$B$231 -> 5 | F7: =Final_evaluation!$C$231 -> 3 | G7: =C7/B7 -> 0.23333333 | H7: =D7/B7 -> 0.1 | I7: =E7/B7 -> 0.16666667 | J7: =F7/B7 -> 0.1 | K7: =($B$7/2-$E$7)/(($B$7/2-$E$7)+$C$7) -> 0.58823529 | L7: =($B$7/2-$F$7)/(($B$7/2-$F$7)+$D$7) -> 0.8 | M7: =($B$7/2-$E$7)/($B$7/2) -> 0.66666667 | N7: =($B$7/2-$F$7)/($B$7/2) -> 0.8 | O7: =$K$7*$M$7*2/($K$7+$M$7) -> 0.625 | P7: =$L$7*$N$7*2/($L$7+$N$7) -> 0.8 | Q7: =($B$7-$C$7-$E$7)/$B$7 -> 0.6 | R7: =($B$7-$D$7-$F$7)/$B$7 -> 0.8
A8: numpy | B8: 30 | C8: =Final_evaluation!$B$232 -> 7 | D8: =Final_evaluation!$C$232 -> 10 | E8: =Final_evaluation!$B$233 -> 9 | F8: =Final_evaluation!$C$233 -> 8 | G8: =C8/B8 -> 0.23333333 | H8: =D8/B8 -> 0.33333333 | I8: =E8/B8 -> 0.3 | J8: =F8/B8 -> 0.26666667 | K8: =($B$8/2-$E$8)/(($B$8/2-$E$8)+$C$8) -> 0.46153846 | L8: =($B$8/2-$F$8)/(($B$8/2-$F$8)+$D$8) -> 0.41176471 | M8: =($B$8/2-$E$8)/($B$8/2) -> 0.4 | N8: =($B$8/2-$F$8)/($B$8/2) -> 0.46666667 | O8: =$K$8*$M$8*2/($K$8+$M$8) -> 0.42857143 | P8: =$L$8*$N$8*2/($L$8+$N$8) -> 0.4375 | Q8: =($B$8-$C$8-$E$8)/$B$8 -> 0.46666667 | R8: =($B$8-$D$8-$F$8)/$B$8 -> 0.4 | T8: Diff | V8: Prec | X8: Rec | Z8: F1 | AB8: Acc
A9: other | B9: 32 | C9: =Final_evaluation!$B$234 -> 7 | D9: =Final_evaluation!$C$234 -> 6 | E9: =Final_evaluation!$B$235 -> 8 | F9: =Final_evaluation!$C$235 -> 6 | G9: =C9/B9 -> 0.21875 | H9: =D9/B9 -> 0.1875 | I9: =E9/B9 -> 0.25 | J9: =F9/B9 -> 0.1875 | K9: =($B$9/2-$E$9)/(($B$9/2-$E$9)+$C$9) -> 0.53333333 | L9: =($B$9/2-$F$9)/(($B$9/2-$F$9)+$D$9) -> 0.625 | M9: =($B$9/2-$E$9)/($B$9/2) -> 0.5 | N9: =($B$9/2-$F$9)/($B$9/2) -> 0.625 | O9: =$K$9*$M$9*2/($K$9+$M$9) -> 0.51612903 | P9: =$L$9*$N$9*2/($L$9+$N$9) -> 0.625 | Q9: =($B$9-$C$9-$E$9)/$B$9 -> 0.53125 | R9: =($B$9-$D$9-$F$9)/$B$9 -> 0.625 | T9: LLM - gemini | V9: =V4-U4 -> 0.0578125 | X9: =X4-W4 -> 0.10810811 | Z9: =Z4-Y4 -> 0.08042167 | AB9: =AB4-AA4 -> 0.072072072
A10: NBspecific | B10: 40 | C10: =Final_evaluation!$B$236 -> 6 | D10: =Final_evaluation!$C$236 -> 3 | E10: =Final_evaluation!$B$237 -> 0 | F10: =Final_evaluation!$C$237 -> 0 | G10: =C10/B10 -> 0.15 | H10: =D10/B10 -> 0.075 | I10: =E10/B10 -> 0 | J10: =F10/B10 -> 0 | K10: =($B$10/2-$E$10)/(($B$10/2-$E$10)+$C$10) -> 0.76923077 | L10: =($B$10/2-$F$10)/(($B$10/2-$F$10)+$D$10) -> 0.86956522 | M10: =($B$10/2-$E$10)/($B$10/2) -> 1 | N10: =($B$10/2-$F$10)/($B$10/2) -> 1 | O10: =$K$10*$M$10*2/($K$10+$M$10) -> 0.86956522 | P10: =$L$10*$N$10*2/($L$10+$N$10) -> 0.93023256 | Q10: =($B$10-$C$10-$E$10)/$B$10 -> 0.85 | R10: =($B$10-$D$10-$F$10)/$B$10 -> 0.925 | T10: LLM - qwen | V10: =V5-U5 -> 0.16313904 | X10: =X5-W5 -> 0.054054054 | Z10: =Z5-Y5 -> 0.092950683 | AB10: =AB5-AA5 -> 0.094594595
A11: total | B11: =SUM(B4:B10) -> 222 | C11: =SUM(C4:C10) -> 51 | D11: =SUM(D4:D10) -> 47 | E11: =SUM(E4:E10) -> 42 | F11: =SUM(F4:F10) -> 30 | G11: =C11/B11 -> 0.22972973 | H11: =D11/B11 -> 0.21171171 | I11: =E11/B11 -> 0.18918919 | J11: =F11/B11 -> 0.13513514 | K11: =($B$11/2-$E$11)/(($B$11/2-$E$11)+$C$11) -> 0.575 | L11: =($B$11/2-$F$11)/(($B$11/2-$F$11)+$D$11) -> 0.6328125 | M11: =($B$11/2-$E$11)/($B$11/2) -> 0.62162162 | N11: =($B$11/2-$F$11)/($B$11/2) -> 0.72972973 | O11: =$K$11*$M$11*2/($K$11+$M$11) -> 0.5974026 | P11: =$L$11*$N$11*2/($L$11+$N$11) -> 0.67782427 | Q11: =($B$11-$C$11-$E$11)/$B$11 -> 0.58108108 | R11: =($B$11-$D$11-$F$11)/$B$11 -> 0.65315315 | T11: LLM - gpt5 | V11: =V6-U6 -> 0.047979798 | X11: =X6-W6 -> 0.14414414 | Z11: =Z6-Y6 -> 0.10622711 | AB11: =AB6-AA6 -> 0.076576577
A14: qwen 2.5 32b instruct | B14: Count | C14: H | D14: FP+RT | E14: FN-RT | F14: FN+RT | G14: FPR-RT | H14: FPR+RT | I14: FNR-RT | J14: FNR+RT | K14: Prec-RT | L14: Prec+RT | M14: Rec-RT | N14: Rec+RT | O14: F1-RT | P14: F1+RT | Q14: Acc-RT | R14: Acc+RT
A15: tensorflow | B15: 30 | C15: =Final_evaluation!$D$224 -> 5 | D15: =Final_evaluation!$E$224 -> 0 | E15: =Final_evaluation!$D$225 -> 3 | F15: =Final_evaluation!$E$225 -> 3 | G15: =C15/B15 -> 0.16666667 | H15: =D15/B15 -> 0 | I15: =E15/B15 -> 0.1 | J15: =F15/B15 -> 0.1 | K15: =($B$15/2-$E$15)/(($B$15/2-$E$15)+$C$15) -> 0.70588235 | L15: =($B$15/2-$F$15)/(($B$15/2-$F$15)+$D$15) -> 1 | M15: =($B$15/2-$E$15)/($B$15/2) -> 0.8 | N15: =($B$15/2-$F$15)/($B$15/2) -> 0.8 | O15: =$K$15*$M$15*2/($K$15+$M$15) -> 0.75 | P15: =$L$15*$N$15*2/($L$15+$N$15) -> 0.88888889 | Q15: =($B$15-$C$15-$E$15)/$B$15 -> 0.73333333 | R15: =($B$15-$D$15-$F$15)/$B$15 -> 0.9
A16: torch | B16: 30 | C16: =Final_evaluation!$D$226 -> 5 | D16: =Final_evaluation!$E$226 -> 5 | E16: =Final_evaluation!$D$227 -> 14 | F16: =Final_evaluation!$E$227 -> 12 | G16: =C16/B16 -> 0.16666667 | H16: =D16/B16 -> 0.16666667 | I16: =E16/B16 -> 0.46666667 | J16: =F16/B16 -> 0.4 | K16: =($B$16/2-$E$16)/(($B$16/2-$E$16)+$C$16) -> 0.16666667 | L16: =($B$16/2-$F$16)/(($B$16/2-$F$16)+$D$16) -> 0.375 | M16: =($B$16/2-$E$16)/($B$16/2) -> 0.066666667 | N16: =($B$16/2-$F$16)/($B$16/2) -> 0.2 | O16: =$K$16*$M$16*2/($K$16+$M$16) -> 0.095238095 | P16: =$L$16*$N$16*2/($L$16+$N$16) -> 0.26086957 | Q16: =($B$16-$C$16-$E$16)/$B$16 -> 0.36666667 | R16: =($B$16-$D$16-$F$16)/$B$16 -> 0.43333333
A17: sklearn | B17: 30 | C17: =Final_evaluation!$D$228 -> 2 | D17: =Final_evaluation!$E$228 -> 1 | E17: =Final_evaluation!$D$229 -> 8 | F17: =Final_evaluation!$E$229 -> 5 | G17: =C17/B17 -> 0.066666667 | H17: =D17/B17 -> 0.033333333 | I17: =E17/B17 -> 0.26666667 | J17: =F17/B17 -> 0.16666667 | K17: =($B$17/2-$E$17)/(($B$17/2-$E$17)+$C$17) -> 0.77777778 | L17: =($B$17/2-$F$17)/(($B$17/2-$F$17)+$D$17) -> 0.90909091 | M17: =($B$17/2-$E$17)/($B$17/2) -> 0.46666667 | N17: =($B$17/2-$F$17)/($B$17/2) -> 0.66666667 | O17: =$K$17*$M$17*2/($K$17+$M$17) -> 0.58333333 | P17: =$L$17*$N$17*2/($L$17+$N$17) -> 0.76923077 | Q17: =($B$17-$C$17-$E$17)/$B$17 -> 0.66666667 | R17: =($B$17-$D$17-$F$17)/$B$17 -> 0.8
A18: pandas | B18: 30 | C18: =Final_evaluation!$D$230 -> 5 | D18: =Final_evaluation!$E$230 -> 2 | E18: =Final_evaluation!$D$231 -> 7 | F18: =Final_evaluation!$E$231 -> 6 | G18: =C18/B18 -> 0.16666667 | H18: =D18/B18 -> 0.066666667 | I18: =E18/B18 -> 0.23333333 | J18: =F18/B18 -> 0.2 | K18: =($B$18/2-$E$18)/(($B$18/2-$E$18)+$C$18) -> 0.61538462 | L18: =($B$18/2-$F$18)/(($B$18/2-$F$18)+$D$18) -> 0.81818182 | M18: =($B$18/2-$E$18)/($B$18/2) -> 0.53333333 | N18: =($B$18/2-$F$18)/($B$18/2) -> 0.6 | O18: =$K$18*$M$18*2/($K$18+$M$18) -> 0.57142857 | P18: =$L$18*$N$18*2/($L$18+$N$18) -> 0.69230769 | Q18: =($B$18-$C$18-$E$18)/$B$18 -> 0.6 | R18: =($B$18-$D$18-$F$18)/$B$18 -> 0.73333333
A19: numpy | B19: 30 | C19: =Final_evaluation!$D$232 -> 5 | D19: =Final_evaluation!$E$232 -> 2 | E19: =Final_evaluation!$D$233 -> 12 | F19: =Final_evaluation!$E$233 -> 11 | G19: =C19/B19 -> 0.16666667 | H19: =D19/B19 -> 0.066666667 | I19: =E19/B19 -> 0.4 | J19: =F19/B19 -> 0.36666667 | K19: =($B$19/2-$E$19)/(($B$19/2-$E$19)+$C$19) -> 0.375 | L19: =($B$19/2-$F$19)/(($B$19/2-$F$19)+$D$19) -> 0.66666667 | M19: =($B$19/2-$E$19)/($B$19/2) -> 0.2 | N19: =($B$19/2-$F$19)/($B$19/2) -> 0.26666667 | O19: =$K$19*$M$19*2/($K$19+$M$19) -> 0.26086957 | P19: =$L$19*$N$19*2/($L$19+$N$19) -> 0.38095238 | Q19: =($B$19-$C$19-$E$19)/$B$19 -> 0.43333333 | R19: =($B$19-$D$19-$F$19)/$B$19 -> 0.56666667
A20: other | B20: 32 | C20: =Final_evaluation!$D$234 -> 4 | D20: =Final_evaluation!$E$234 -> 2 | E20: =Final_evaluation!$D$235 -> 11 | F20: =Final_evaluation!$E$235 -> 10 | G20: =C20/B20 -> 0.125 | H20: =D20/B20 -> 0.0625 | I20: =E20/B20 -> 0.34375 | J20: =F20/B20 -> 0.3125 | K20: =($B$20/2-$E$20)/(($B$20/2-$E$20)+$C$20) -> 0.55555556 | L20: =($B$20/2-$F$20)/(($B$20/2-$F$20)+$D$20) -> 0.75 | M20: =($B$20/2-$E$20)/($B$20/2) -> 0.3125 | N20: =($B$20/2-$F$20)/($B$20/2) -> 0.375 | O20: =$K$20*$M$20*2/($K$20+$M$20) -> 0.4 | P20: =$L$20*$N$20*2/($L$20+$N$20) -> 0.5 | Q20: =($B$20-$C$20-$E$20)/$B$20 -> 0.53125 | R20: =($B$20-$D$20-$F$20)/$B$20 -> 0.625
A21: NBspecific | B21: 40 | C21: =Final_evaluation!$D$236 -> 1 | D21: =Final_evaluation!$E$236 -> 0 | E21: =Final_evaluation!$D$237 -> 0 | F21: =Final_evaluation!$E$237 -> 2 | G21: =C21/B21 -> 0.025 | H21: =D21/B21 -> 0 | I21: =E21/B21 -> 0 | J21: =F21/B21 -> 0.05 | K21: =($B$21/2-$E$21)/(($B$21/2-$E$21)+$C$21) -> 0.95238095 | L21: =($B$21/2-$F$21)/(($B$21/2-$F$21)+$D$21) -> 1 | M21: =($B$21/2-$E$21)/($B$21/2) -> 1 | N21: =($B$21/2-$F$21)/($B$21/2) -> 0.9 | O21: =$K$21*$M$21*2/($K$21+$M$21) -> 0.97560976 | P21: =$L$21*$N$21*2/($L$21+$N$21) -> 0.94736842 | Q21: =($B$21-$C$21-$E$21)/$B$21 -> 0.975 | R21: =($B$21-$D$21-$F$21)/$B$21 -> 0.95
A22: total | B22: =SUM(B15:B21) -> 222 | C22: =SUM(C15:C21) -> 27 | D22: =SUM(D15:D21) -> 12 | E22: =SUM(E15:E21) -> 55 | F22: =SUM(F15:F21) -> 49 | G22: =C22/B22 -> 0.12162162 | H22: =D22/B22 -> 0.054054054 | I22: =E22/B22 -> 0.24774775 | J22: =F22/B22 -> 0.22072072 | K22: =($B$22/2-$E$22)/(($B$22/2-$E$22)+$C$22) -> 0.6746988 | L22: =($B$22/2-$F$22)/(($B$22/2-$F$22)+$D$22) -> 0.83783784 | M22: =($B$22/2-$E$22)/($B$22/2) -> 0.5045045 | N22: =($B$22/2-$F$22)/($B$22/2) -> 0.55855856 | O22: =$K$22*$M$22*2/($K$22+$M$22) -> 0.57731959 | P22: =$L$22*$N$22*2/($L$22+$N$22) -> 0.67027027 | Q22: =($B$22-$C$22-$E$22)/$B$22 -> 0.63063063 | R22: =($B$22-$D$22-$F$22)/$B$22 -> 0.72522523
A25: gpt 5 | B25: Count | C25: FP-RT | D25: FP+RT | E25: FN-RT | F25: FN+RT | G25: FPR-RT | H25: FPR+RT | I25: FNR-RT | J25: FNR+RT | K25: Prec-RT | L25: Prec+RT | M25: Rec-RT | N25: Rec+RT | O25: F1-RT | P25: F1+RT | Q25: Acc-RT | R25: Acc+RT
A26: tensorflow | B26: 30 | C26: =Final_evaluation!$F$224 -> 3 | D26: =Final_evaluation!$G$224 -> 2 | E26: =Final_evaluation!$F$225 -> 4 | F26: =Final_evaluation!$G$225 -> 3 | G26: =C26/B26 -> 0.1 | H26: =D26/B26 -> 0.066666667 | I26: =E26/B26 -> 0.13333333 | J26: =F26/B26 -> 0.1 | K26: =($B$26/2-$E$26)/(($B$26/2-$E$26)+$C$26) -> 0.78571429 | L26: =($B$26/2-$F$26)/(($B$26/2-$F$26)+$D$26) -> 0.85714286 | M26: =($B$26/2-$E$26)/($B$26/2) -> 0.73333333 | N26: =($B$26/2-$F$26)/($B$26/2) -> 0.8 | O26: =$K$26*$M$26*2/($K$26+$M$26) -> 0.75862069 | P26: =$L$26*$N$26*2/($L$26+$N$26) -> 0.82758621 | Q26: =($B$26-$C$26-$E$26)/$B$26 -> 0.76666667 | R26: =($B$26-$D$26-$F$26)/$B$26 -> 0.83333333
A27: torch | B27: 30 | C27: =Final_evaluation!$F$226 -> 3 | D27: =Final_evaluation!$G$226 -> 5 | E27: =Final_evaluation!$F$227 -> 11 | F27: =Final_evaluation!$G$227 -> 6 | G27: =C27/B27 -> 0.1 | H27: =D27/B27 -> 0.16666667 | I27: =E27/B27 -> 0.36666667 | J27: =F27/B27 -> 0.2 | K27: =($B$27/2-$E$27)/(($B$27/2-$E$27)+$C$27) -> 0.57142857 | L27: =($B$27/2-$F$27)/(($B$27/2-$F$27)+$D$27) -> 0.64285714 | M27: =($B$27/2-$E$27)/($B$27/2) -> 0.26666667 | N27: =($B$27/2-$F$27)/($B$27/2) -> 0.6 | O27: =$K$27*$M$27*2/($K$27+$M$27) -> 0.36363636 | P27: =$L$27*$N$27*2/($L$27+$N$27) -> 0.62068966 | Q27: =($B$27-$C$27-$E$27)/$B$27 -> 0.53333333 | R27: =($B$27-$D$27-$F$27)/$B$27 -> 0.63333333
A28: sklearn | B28: 30 | C28: =Final_evaluation!$F$228 -> 2 | D28: =Final_evaluation!$G$228 -> 3 | E28: =Final_evaluation!$F$229 -> 4 | F28: =Final_evaluation!$G$229 -> 1 | G28: =C28/B28 -> 0.066666667 | H28: =D28/B28 -> 0.1 | I28: =E28/B28 -> 0.13333333 | J28: =F28/B28 -> 0.033333333 | K28: =($B$28/2-$E$28)/(($B$28/2-$E$28)+$C$28) -> 0.84615385 | L28: =($B$28/2-$F$28)/(($B$28/2-$F$28)+$D$28) -> 0.82352941 | M28: =($B$28/2-$E$28)/($B$28/2) -> 0.73333333 | N28: =($B$28/2-$F$28)/($B$28/2) -> 0.93333333 | O28: =$K$28*$M$28*2/($K$28+$M$28) -> 0.78571429 | P28: =$L$28*$N$28*2/($L$28+$N$28) -> 0.875 | Q28: =($B$28-$C$28-$E$28)/$B$28 -> 0.8 | R28: =($B$28-$D$28-$F$28)/$B$28 -> 0.86666667
A29: pandas | B29: 30 | C29: =Final_evaluation!$F$230 -> 5 | D29: =Final_evaluation!$G$230 -> 2 | E29: =Final_evaluation!$F$231 -> 11 | F29: =Final_evaluation!$G$231 -> 8 | G29: =C29/B29 -> 0.16666667 | H29: =D29/B29 -> 0.066666667 | I29: =E29/B29 -> 0.36666667 | J29: =F29/B29 -> 0.26666667 | K29: =($B$29/2-$E$29)/(($B$29/2-$E$29)+$C$29) -> 0.44444444 | L29: =($B$29/2-$F$29)/(($B$29/2-$F$29)+$D$29) -> 0.77777778 | M29: =($B$29/2-$E$29)/($B$29/2) -> 0.26666667 | N29: =($B$29/2-$F$29)/($B$29/2) -> 0.46666667 | O29: =$K$29*$M$29*2/($K$29+$M$29) -> 0.33333333 | P29: =$L$29*$N$29*2/($L$29+$N$29) -> 0.58333333 | Q29: =($B$29-$C$29-$E$29)/$B$29 -> 0.46666667 | R29: =($B$29-$D$29-$F$29)/$B$29 -> 0.66666667
A30: numpy | B30: 30 | C30: =Final_evaluation!$F$232 -> 4 | D30: =Final_evaluation!$G$232 -> 3 | E30: =Final_evaluation!$F$233 -> 6 | F30: =Final_evaluation!$G$233 -> 7 | G30: =C30/B30 -> 0.13333333 | H30: =D30/B30 -> 0.1 | I30: =E30/B30 -> 0.2 | J30: =F30/B30 -> 0.23333333 | K30: =($B$30/2-$E$30)/(($B$30/2-$E$30)+$C$30) -> 0.69230769 | L30: =($B$30/2-$F$30)/(($B$30/2-$F$30)+$D$30) -> 0.72727273 | M30: =($B$30/2-$E$30)/($B$30/2) -> 0.6 | N30: =($B$30/2-$F$30)/($B$30/2) -> 0.53333333 | O30: =$K$30*$M$30*2/($K$30+$M$30) -> 0.64285714 | P30: =$L$30*$N$30*2/($L$30+$N$30) -> 0.61538462 | Q30: =($B$30-$C$30-$E$30)/$B$30 -> 0.66666667 | R30: =($B$30-$D$30-$F$30)/$B$30 -> 0.66666667
A31: other | B31: 32 | C31: =Final_evaluation!$F$234 -> 3 | D31: =Final_evaluation!$G$234 -> 4 | E31: =Final_evaluation!$F$235 -> 9 | F31: =Final_evaluation!$G$235 -> 6 | G31: =C31/B31 -> 0.09375 | H31: =D31/B31 -> 0.125 | I31: =E31/B31 -> 0.28125 | J31: =F31/B31 -> 0.1875 | K31: =($B$31/2-$E$31)/(($B$31/2-$E$31)+$C$31) -> 0.7 | L31: =($B$31/2-$F$31)/(($B$31/2-$F$31)+$D$31) -> 0.71428571 | M31: =($B$31/2-$E$31)/($B$31/2) -> 0.4375 | N31: =($B$31/2-$F$31)/($B$31/2) -> 0.625 | O31: =$K$31*$M$31*2/($K$31+$M$31) -> 0.53846154 | P31: =$L$31*$N$31*2/($L$31+$N$31) -> 0.66666667 | Q31: =($B$31-$C$31-$E$31)/$B$31 -> 0.625 | R31: =($B$31-$D$31-$F$31)/$B$31 -> 0.6875
A32: NBspecific | B32: 40 | C32: =Final_evaluation!$F$236 -> 1 | D32: =Final_evaluation!$G$236 -> 1 | E32: =Final_evaluation!$F$237 -> 3 | F32: =Final_evaluation!$G$237 -> 1 | G32: =C32/B32 -> 0.025 | H32: =D32/B32 -> 0.025 | I32: =E32/B32 -> 0.075 | J32: =F32/B32 -> 0.025 | K32: =($B$32/2-$E$32)/(($B$32/2-$E$32)+$C$32) -> 0.94444444 | L32: =($B$32/2-$F$32)/(($B$32/2-$F$32)+$D$32) -> 0.95 | M32: =($B$32/2-$E$32)/($B$32/2) -> 0.85 | N32: =($B$32/2-$F$32)/($B$32/2) -> 0.95 | O32: =$K$32*$M$32*2/($K$32+$M$32) -> 0.89473684 | P32: =$L$32*$N$32*2/($L$32+$N$32) -> 0.95 | Q32: =($B$32-$C$32-$E$32)/$B$32 -> 0.9 | R32: =($B$32-$D$32-$F$32)/$B$32 -> 0.95
A33: total | B33: =SUM(B26:B32) -> 222 | C33: =SUM(C26:C32) -> 21 | D33: =SUM(D26:D32) -> 20 | E33: =SUM(E26:E32) -> 48 | F33: =SUM(F26:F32) -> 32 | G33: =C33/B33 -> 0.094594595 | H33: =D33/B33 -> 0.09009009 | I33: =E33/B33 -> 0.21621622 | J33: =F33/B33 -> 0.14414414 | K33: =($B$33/2-$E$33)/(($B$33/2-$E$33)+$C$33) -> 0.75 | L33: =($B$33/2-$F$33)/(($B$33/2-$F$33)+$D$33) -> 0.7979798 | M33: =($B$33/2-$E$33)/($B$33/2) -> 0.56756757 | N33: =($B$33/2-$F$33)/($B$33/2) -> 0.71171171 | O33: =$K$33*$M$33*2/($K$33+$M$33) -> 0.64615385 | P33: =$L$33*$N$33*2/($L$33+$N$33) -> 0.75238095 | Q33: =($B$33-$C$33-$E$33)/$B$33 -> 0.68918919 | R33: =($B$33-$D$33-$F$33)/$B$33 -> 0.76576577
