Workbook

Sheet Final_evaluation
A1: instance | B1: crash_detection_gemini_code | C1: crash_detection_gemini_runinfo | D1: crash_detection_gemini_runinfo_full_doc | E1: crash_detection_gemini_runinfo_r_v | F1: crash_detection_gemini_runinfo_s_r | G1: crash_detection_gemini_runinfo_s_v | H1: crash_detection_qwen_code | I1: crash_detection_qwen_runinfo | J1: crash_detection_qwen_runinfo_full_doc | K1: crash_detection_qwen_runinfo_r_v | L1: crash_detection_qwen_runinfo_s_r | M1: crash_detection_qwen_runinfo_s_v | N1: crash_detection_gpt5_code | O1: crash_detection_gpt5_runinfo | P1: crash_detection_gpt5_runinfo_full_doc | Q1: crash_detection_gpt5_runinfo_r_v | R1: crash_detection_gpt5_runinfo_s_r | S1: crash_detection_gpt5_runinfo_s_v
A2: tensorflow_1_fixed | B2: correct | C2: correct | D2: correct | E2: correct | F2: correct | G2: correct | H2: correct | I2: correct | J2: correct | K2: correct | L2: correct | M2: correct | N2: correct | O2: correct | P2: correct | Q2: correct | R2: correct | S2: correct
A3: tensorflow_2_fixed | B3: correct | C3: wrong | D3: wrong | E3: correct | F3: wrong | G3: wrong | H3: correct | I3: correct | J3: correct | K3: correct | L3: correct | M3: correct | N3: correct | O3: correct | P3: correct | Q3: correct | R3: correct | S3: correct
A4: tensorflow_3_fixed | B4: correct | C4: correct | D4: correct | E4: correct | F4: correct | G4: correct | H4: correct | I4: correct | J4: correct | K4: correct | L4: correct | M4: correct | N4: correct | O4: correct | P4: correct | Q4: correct | R4: correct | S4: correct
A5: tensorflow_4_fixed | B5: wrong | C5: wrong | D5: wrong | E5: wrong | F5: wrong | G5: wrong | H5: correct | I5: correct | J5: correct | K5: correct | L5: correct | M5: correct | N5: wrong | O5: wrong | P5: wrong | Q5: correct | R5: wrong | S5: correct
A6: tensorflow_5_fixed | B6: wrong | C6: wrong | D6: wrong | E6: wrong | F6: wrong | G6: wrong | H6: correct | I6: correct | J6: correct | K6: correct | L6: correct | M6: correct | N6: correct | O6: correct | P6: correct | Q6: correct | R6: correct | S6: correct
A7: tensorflow_6_fixed | B7: wrong | C7: wrong | D7: wrong | E7: wrong | F7: correct | G7: wrong | H7: wrong | I7: correct | J7: correct | K7: correct | L7: correct | M7: correct | N7: correct | O7: correct | P7: correct | Q7: correct | R7: correct | S7: correct
A8: tensorflow_7_fixed | B8: correct | C8: wrong | D8: wrong | E8: wrong | F8: wrong | G8: wrong | H8: wrong | I8: correct | J8: correct | K8: correct | L8: correct | M8: correct | N8: correct | O8: correct | P8: correct | Q8: correct | R8: correct | S8: correct
A9: tensorflow_8_fixed | B9: wrong | C9: wrong | D9: wrong | E9: wrong | F9: wrong | G9: wrong | H9: correct | I9: correct | J9: correct | K9: correct | L9: wrong | M9: wrong | N9: correct | O9: correct | P9: wrong | Q9: wrong | R9: wrong | S9: wrong
A10: tensorflow_9_fixed | B10: wrong | C10: correct | D10: correct | E10: correct | F10: correct | G10: wrong | H10: wrong | I10: correct | J10: correct | K10: wrong | L10: wrong | M10: wrong | N10: correct | O10: correct | P10: correct | Q10: correct | R10: correct | S10: correct
A11: tensorflow_10_fixed | B11: wrong | C11: wrong | D11: correct | E11: correct | F11: correct | G11: wrong | H11: wrong | I11: correct | J11: correct | K11: correct | L11: correct | M11: wrong | N11: correct | O11: correct | P11: correct | Q11: correct | R11: correct | S11: correct
A12: tensorflow_11_fixed | B12: wrong | C12: wrong | D12: wrong | E12: wrong | F12: wrong | G12: wrong | H12: correct | I12: correct | J12: correct | K12: correct | L12: correct | M12: correct | N12: correct | O12: correct | P12: correct | Q12: correct | R12: correct | S12: correct
... A223: NBspecific_20_reproduced | B223: correct | C223: correct | D223: correct | E223: correct | F223: correct | G223: correct | H223: correct | I223: correct | J223: correct | K223: correct | L223: correct | M223: correct | N223: correct | O223: correct | P223: correct | Q223: correct | R223: correct | S223: correct
A224: FP_tensorflow | B224: {=SUM(COUNTIF(Final_evaluation!$B$2:'Final_evaluation'!$B$16, {"<>correct"}))} -> 9 | C224: {=SUM(COUNTIF(Final_evaluation!$C$2:'Final_evaluation'!$C$16, {"<>correct"}))} -> 11 | D224: {=SUM(COUNTIF(Final_evaluation!$D$2:'Final_evaluation'!$D$16, {"<>correct"}))} -> 9 | E224: {=SUM(COUNTIF(Final_evaluation!$E$2:'Final_evaluation'!$E$16, {"<>correct"}))} -> 8 | F224: {=SUM(COUNTIF(Final_evaluation!$F$2:'Final_evaluation'!$F$16, {"<>correct"}))} -> 8 | G224: {=SUM(COUNTIF(Final_evaluation!$G$2:'Final_evaluation'!$G$16, {"<>correct"}))} -> 11 | H224: {=SUM(COUNTIF(Final_evaluation!$H$2:'Final_evaluation'!$H$16, {"<>correct"}))} -> 5 | I224: {=SUM(COUNTIF(Final_evaluation!$I$2:'Final_evaluation'!$I$16, {"<>correct"}))} -> 0 | J224: {=SUM(COUNTIF(Final_evaluation!$J$2:'Final_evaluation'!$J$16, {"<>correct"}))} -> 0 | K224: {=SUM(COUNTIF(Final_evaluation!$K$2:'Final_evaluation'!$K$16, {"<>correct"}))} -> 2 | L224: {=SUM(COUNTIF(Final_evaluation!$L$2:'Final_evaluation'!$L$16, {"<>correct"}))} -> 2 | M224: {=SUM(COUNTIF(Final_evaluation!$M$2:'Final_evaluation'!$M$16, {"<>correct"}))} -> 4 | N224: {=SUM(COUNTIF(Final_evaluation!$N$2:'Final_evaluation'!$N$16, {"<>correct"}))} -> 3 | O224: {=SUM(COUNTIF(Final_evaluation!$O$2:'Final_evaluation'!$O$16, {"<>correct"}))} -> 2 | P224: {=SUM(COUNTIF(Final_evaluation!$P$2:'Final_evaluation'!$P$16, {"<>correct"}))} -> 3 | Q224: {=SUM(COUNTIF(Final_evaluation!$Q$2:'Final_evaluation'!$Q$16, {"<>correct"}))} -> 2 | R224: {=SUM(COUNTIF(Final_evaluation!$R$2:'Final_evaluation'!$R$16, {"<>correct"}))} -> 3 | S224: {=SUM(COUNTIF(Final_evaluation!$S$2:'Final_evaluation'!$S$16, {"<>correct"}))} -> 3
A225: FN_tensorflow | B225: {=SUM(COUNTIF(Final_evaluation!$B$17:'Final_evaluation'!$B$31, {"<>correct"}))} -> 2 | C225: {=SUM(COUNTIF(Final_evaluation!$C$17:'Final_evaluation'!$C$31, {"<>correct"}))} -> 1 | D225: {=SUM(COUNTIF(Final_evaluation!$D$17:'Final_evaluation'!$D$31, {"<>correct"}))} -> 1 | E225: {=SUM(COUNTIF(Final_evaluation!$E$17:'Final_evaluation'!$E$31, {"<>correct"}))} -> 1 | F225: {=SUM(COUNTIF(Final_evaluation!$F$17:'Final_evaluation'!$F$31, {"<>correct"}))} -> 2 | G225: {=SUM(COUNTIF(Final_evaluation!$G$17:'Final_evaluation'!$G$31, {"<>correct"}))} -> 1 | H225: {=SUM(COUNTIF(Final_evaluation!$H$17:'Final_evaluation'!$H$31, {"<>correct"}))} -> 3 | I225: {=SUM(COUNTIF(Final_evaluation!$I$17:'Final_evaluation'!$I$31, {"<>correct"}))} -> 2 | J225: {=SUM(COUNTIF(Final_evaluation!$J$17:'Final_evaluation'!$J$31, {"<>correct"}))} -> 3 | K225: {=SUM(COUNTIF(Final_evaluation!$K$17:'Final_evaluation'!$K$31, {"<>correct"}))} -> 3 | L225: {=SUM(COUNTIF(Final_evaluation!$L$17:'Final_evaluation'!$L$31, {"<>correct"}))} -> 3 | M225: {=SUM(COUNTIF(Final_evaluation!$M$17:'Final_evaluation'!$M$31, {"<>correct"}))} -> 2 | N225: {=SUM(COUNTIF(Final_evaluation!$N$17:'Final_evaluation'!$N$31, {"<>correct"}))} -> 2 | O225: {=SUM(COUNTIF(Final_evaluation!$O$17:'Final_evaluation'!$O$31, {"<>correct"}))} -> 3 | P225: {=SUM(COUNTIF(Final_evaluation!$P$17:'Final_evaluation'!$P$31, {"<>correct"}))} -> 2 | Q225: {=SUM(COUNTIF(Final_evaluation!$Q$17:'Final_evaluation'!$Q$31, {"<>correct"}))} -> 2 | R225: {=SUM(COUNTIF(Final_evaluation!$R$17:'Final_evaluation'!$R$31, {"<>correct"}))} -> 3 | S225: {=SUM(COUNTIF(Final_evaluation!$S$17:'Final_evaluation'!$S$31, {"<>correct"}))} -> 2
A226: FP_torch | B226: {=SUM(COUNTIF(Final_evaluation!$B$32:'Final_evaluation'!$B$46, {"<>correct"}))} -> 10 | C226: {=SUM(COUNTIF(Final_evaluation!$C$32:'Final_evaluation'!$C$46, {"<>correct"}))} -> 10 | D226: {=SUM(COUNTIF(Final_evaluation!$D$32:'Final_evaluation'!$D$46, {"<>correct"}))} -> 7 | E226: {=SUM(COUNTIF(Final_evaluation!$E$32:'Final_evaluation'!$E$46, {"<>correct"}))} -> 9 | F226: {=SUM(COUNTIF(Final_evaluation!$F$32:'Final_evaluation'!$F$46, {"<>correct"}))} -> 5 | G226: {=SUM(COUNTIF(Final_evaluation!$G$32:'Final_evaluation'!$G$46, {"<>correct"}))} -> 8 | H226: {=SUM(COUNTIF(Final_evaluation!$H$32:'Final_evaluation'!$H$46, {"<>correct"}))} -> 5 | I226: {=SUM(COUNTIF(Final_evaluation!$I$32:'Final_evaluation'!$I$46, {"<>correct"}))} -> 5 | J226: {=SUM(COUNTIF(Final_evaluation!$J$32:'Final_evaluation'!$J$46, {"<>correct"}))} -> 5 | K226: {=SUM(COUNTIF(Final_evaluation!$K$32:'Final_evaluation'!$K$46, {"<>correct"}))} -> 4 | L226: {=SUM(COUNTIF(Final_evaluation!$L$32:'Final_evaluation'!$L$46, {"<>correct"}))} -> 3 | M226: {=SUM(COUNTIF(Final_evaluation!$M$32:'Final_evaluation'!$M$46, {"<>correct"}))} -> 6 | N226: {=SUM(COUNTIF(Final_evaluation!$N$32:'Final_evaluation'!$N$46, {"<>correct"}))} -> 3 | O226: {=SUM(COUNTIF(Final_evaluation!$O$32:'Final_evaluation'!$O$46, {"<>correct"}))} -> 5 | P226: {=SUM(COUNTIF(Final_evaluation!$P$32:'Final_evaluation'!$P$46, {"<>correct"}))} -> 4 | Q226: {=SUM(COUNTIF(Final_evaluation!$Q$32:'Final_evaluation'!$Q$46, {"<>correct"}))} -> 4 | R226: {=SUM(COUNTIF(Final_evaluation!$R$32:'Final_evaluation'!$R$46, {"<>correct"}))} -> 5 | S226: {=SUM(COUNTIF(Final_evaluation!$S$32:'Final_evaluation'!$S$46, {"<>correct"}))} -> 4
A227: FN_torch | B227: {=SUM(COUNTIF(Final_evaluation!$B$47:'Final_evaluation'!$B$61, {"<>correct"}))} -> 4 | C227: {=SUM(COUNTIF(Final_evaluation!$C$47:'Final_evaluation'!$C$61, {"<>correct"}))} -> 2 | D227: {=SUM(COUNTIF(Final_evaluation!$D$47:'Final_evaluation'!$D$61, {"<>correct"}))} -> 2 | E227: {=SUM(COUNTIF(Final_evaluation!$E$47:'Final_evaluation'!$E$61, {"<>correct"}))} -> 4 | F227: {=SUM(COUNTIF(Final_evaluation!$F$47:'Final_evaluation'!$F$61, {"<>correct"}))} -> 5 | G227: {=SUM(COUNTIF(Final_evaluation!$G$47:'Final_evaluation'!$G$61, {"<>correct"}))} -> 2 | H227: {=SUM(COUNTIF(Final_evaluation!$H$47:'Final_evaluation'!$H$61, {"<>correct"}))} -> 9 | I227: {=SUM(COUNTIF(Final_evaluation!$I$47:'Final_evaluation'!$I$61, {"<>correct"}))} -> 7 | J227: {=SUM(COUNTIF(Final_evaluation!$J$47:'Final_evaluation'!$J$61, {"<>correct"}))} -> 10 | K227: {=SUM(COUNTIF(Final_evaluation!$K$47:'Final_evaluation'!$K$61, {"<>correct"}))} -> 11 | L227: {=SUM(COUNTIF(Final_evaluation!$L$47:'Final_evaluation'!$L$61, {"<>correct"}))} -> 11 | M227: {=SUM(COUNTIF(Final_evaluation!$M$47:'Final_evaluation'!$M$61, {"<>correct"}))} -> 6 | N227: {=SUM(COUNTIF(Final_evaluation!$N$47:'Final_evaluation'!$N$61, {"<>correct"}))} -> 5 | O227: {=SUM(COUNTIF(Final_evaluation!$O$47:'Final_evaluation'!$O$61, {"<>correct"}))} -> 3 | P227: {=SUM(COUNTIF(Final_evaluation!$P$47:'Final_evaluation'!$P$61, {"<>correct"}))} -> 3 | Q227: {=SUM(COUNTIF(Final_evaluation!$Q$47:'Final_evaluation'!$Q$61, {"<>correct"}))} -> 4 | R227: {=SUM(COUNTIF(Final_evaluation!$R$47:'Final_evaluation'!$R$61, {"<>correct"}))} -> 5 | S227: {=SUM(COUNTIF(Final_evaluation!$S$47:'Final_evaluation'!$S$61, {"<>correct"}))} -> 4
A228: FP_sklearn | B228: {=SUM(COUNTIF(Final_evaluation!$B$62:'Final_evaluation'!$B$76, {"<>correct"}))} -> 5 | C228: {=SUM(COUNTIF(Final_evaluation!$C$62:'Final_evaluation'!$C$76, {"<>correct"}))} -> 4 | D228: {=SUM(COUNTIF(Final_evaluation!$D$62:'Final_evaluation'!$D$76, {"<>correct"}))} -> 3 | E228: {=SUM(COUNTIF(Final_evaluation!$E$62:'Final_evaluation'!$E$76, {"<>correct"}))} -> 5 | F228: {=SUM(COUNTIF(Final_evaluation!$F$62:'Final_evaluation'!$F$76, {"<>correct"}))} -> 3 | G228: {=SUM(COUNTIF(Final_evaluation!$G$62:'Final_evaluation'!$G$76, {"<>correct"}))} -> 4 | H228: {=SUM(COUNTIF(Final_evaluation!$H$62:'Final_evaluation'!$H$76, {"<>correct"}))} -> 2 | I228: {=SUM(COUNTIF(Final_evaluation!$I$62:'Final_evaluation'!$I$76, {"<>correct"}))} -> 1 | J228: {=SUM(COUNTIF(Final_evaluation!$J$62:'Final_evaluation'!$J$76, {"<>correct"}))} -> 1 | K228: {=SUM(COUNTIF(Final_evaluation!$K$62:'Final_evaluation'!$K$76, {"<>correct"}))} -> 2 | L228: {=SUM(COUNTIF(Final_evaluation!$L$62:'Final_evaluation'!$L$76, {"<>correct"}))} -> 1 | M228: {=SUM(COUNTIF(Final_evaluation!$M$62:'Final_evaluation'!$M$76, {"<>correct"}))} -> 2 | N228: {=SUM(COUNTIF(Final_evaluation!$N$62:'Final_evaluation'!$N$76, {"<>correct"}))} -> 2 | O228: {=SUM(COUNTIF(Final_evaluation!$O$62:'Final_evaluation'!$O$76, {"<>correct"}))} -> 3 | P228: {=SUM(COUNTIF(Final_evaluation!$P$62:'Final_evaluation'!$P$76, {"<>correct"}))} -> 1 | Q228: {=SUM(COUNTIF(Final_evaluation!$Q$62:'Final_evaluation'!$Q$76, {"<>correct"}))} -> 1 | R228: {=SUM(COUNTIF(Final_evaluation!$R$62:'Final_evaluation'!$R$76, {"<>correct"}))} -> 0 | S228: {=SUM(COUNTIF(Final_evaluation!$S$62:'Final_evaluation'!$S$76, {"<>correct"}))} -> 3
A229: FN_sklearn | B229: {=SUM(COUNTIF(Final_evaluation!$B$77:'Final_evaluation'!$B$91, {"<>correct"}))} -> 5 | C229: {=SUM(COUNTIF(Final_evaluation!$C$77:'Final_evaluation'!$C$91, {"<>correct"}))} -> 0 | D229: {=SUM(COUNTIF(Final_evaluation!$D$77:'Final_evaluation'!$D$91, {"<>correct"}))} -> 0 | E229: {=SUM(COUNTIF(Final_evaluation!$E$77:'Final_evaluation'!$E$91, {"<>correct"}))} -> 0 | F229: {=SUM(COUNTIF(Final_evaluation!$F$77:'Final_evaluation'!$F$91, {"<>correct"}))} -> 2 | G229: {=SUM(COUNTIF(Final_evaluation!$G$77:'Final_evaluation'!$G$91, {"<>correct"}))} -> 2 | H229: {=SUM(COUNTIF(Final_evaluation!$H$77:'Final_evaluation'!$H$91, {"<>correct"}))} -> 6 | I229: {=SUM(COUNTIF(Final_evaluation!$I$77:'Final_evaluation'!$I$91, {"<>correct"}))} -> 4 | J229: {=SUM(COUNTIF(Final_evaluation!$J$77:'Final_evaluation'!$J$91, {"<>correct"}))} -> 4 | K229: {=SUM(COUNTIF(Final_evaluation!$K$77:'Final_evaluation'!$K$91, {"<>correct"}))} -> 3 | L229: {=SUM(COUNTIF(Final_evaluation!$L$77:'Final_evaluation'!$L$91, {"<>correct"}))} -> 3 | M229: {=SUM(COUNTIF(Final_evaluation!$M$77:'Final_evaluation'!$M$91, {"<>correct"}))} -> 4 | N229: {=SUM(COUNTIF(Final_evaluation!$N$77:'Final_evaluation'!$N$91, {"<>correct"}))} -> 3 | O229: {=SUM(COUNTIF(Final_evaluation!$O$77:'Final_evaluation'!$O$91, {"<>correct"}))} -> 1 | P229: {=SUM(COUNTIF(Final_evaluation!$P$77:'Final_evaluation'!$P$91, {"<>correct"}))} -> 1 | Q229: {=SUM(COUNTIF(Final_evaluation!$Q$77:'Final_evaluation'!$Q$91, {"<>correct"}))} -> 1 | R229: {=SUM(COUNTIF(Final_evaluation!$R$77:'Final_evaluation'!$R$91, {"<>correct"}))} -> 1 | S229: {=SUM(COUNTIF(Final_evaluation!$S$77:'Final_evaluation'!$S$91, {"<>correct"}))} -> 0
A230: FP_pandas | B230: {=SUM(COUNTIF(Final_evaluation!$B$92:'Final_evaluation'!$B$106, {"<>correct"}))} -> 7 | C230: {=SUM(COUNTIF(Final_evaluation!$C$92:'Final_evaluation'!$C$106, {"<>correct"}))} -> 3 | D230: {=SUM(COUNTIF(Final_evaluation!$D$92:'Final_evaluation'!$D$106, {"<>correct"}))} -> 4 | E230: {=SUM(COUNTIF(Final_evaluation!$E$92:'Final_evaluation'!$E$106, {"<>correct"}))} -> 3 | F230: {=SUM(COUNTIF(Final_evaluation!$F$92:'Final_evaluation'!$F$106, {"<>correct"}))} -> 2 | G230: {=SUM(COUNTIF(Final_evaluation!$G$92:'Final_evaluation'!$G$106, {"<>correct"}))} -> 4 | H230: {=SUM(COUNTIF(Final_evaluation!$H$92:'Final_evaluation'!$H$106, {"<>correct"}))} -> 5 | I230: {=SUM(COUNTIF(Final_evaluation!$I$92:'Final_evaluation'!$I$106, {"<>correct"}))} -> 2 | J230: {=SUM(COUNTIF(Final_evaluation!$J$92:'Final_evaluation'!$J$106, {"<>correct"}))} -> 2 | K230: {=SUM(COUNTIF(Final_evaluation!$K$92:'Final_evaluation'!$K$106, {"<>correct"}))} -> 3 | L230: {=SUM(COUNTIF(Final_evaluation!$L$92:'Final_evaluation'!$L$106, {"<>correct"}))} -> 3 | M230: {=SUM(COUNTIF(Final_evaluation!$M$92:'Final_evaluation'!$M$106, {"<>correct"}))} -> 6 | N230: {=SUM(COUNTIF(Final_evaluation!$N$92:'Final_evaluation'!$N$106, {"<>correct"}))} -> 5 | O230: {=SUM(COUNTIF(Final_evaluation!$O$92:'Final_evaluation'!$O$106, {"<>correct"}))} -> 2 | P230: {=SUM(COUNTIF(Final_evaluation!$P$92:'Final_evaluation'!$P$106, {"<>correct"}))} -> 2 | Q230: {=SUM(COUNTIF(Final_evaluation!$Q$92:'Final_evaluation'!$Q$106, {"<>correct"}))} -> 2 | R230: {=SUM(COUNTIF(Final_evaluation!$R$92:'Final_evaluation'!$R$106, {"<>correct"}))} -> 3 | S230: {=SUM(COUNTIF(Final_evaluation!$S$92:'Final_evaluation'!$S$106, {"<>correct"}))} -> 1
A231: FN_pandas | B231: {=SUM(COUNTIF(Final_evaluation!$B$107:'Final_evaluation'!$B$121, {"<>correct"}))} -> 3 | C231: {=SUM(COUNTIF(Final_evaluation!$C$107:'Final_evaluation'!$C$121, {"<>correct"}))} -> 1 | D231: {=SUM(COUNTIF(Final_evaluation!$D$107:'Final_evaluation'!$D$121, {"<>correct"}))} -> 3 | E231: {=SUM(COUNTIF(Final_evaluation!$E$107:'Final_evaluation'!$E$121, {"<>correct"}))} -> 1 | F231: {=SUM(COUNTIF(Final_evaluation!$F$107:'Final_evaluation'!$F$121, {"<>correct"}))} -> 4 | G231: {=SUM(COUNTIF(Final_evaluation!$G$107:'Final_evaluation'!$G$121, {"<>correct"}))} -> 2 | H231: {=SUM(COUNTIF(Final_evaluation!$H$107:'Final_evaluation'!$H$121, {"<>correct"}))} -> 5 | I231: {=SUM(COUNTIF(Final_evaluation!$I$107:'Final_evaluation'!$I$121, {"<>correct"}))} -> 5 | J231: {=SUM(COUNTIF(Final_evaluation!$J$107:'Final_evaluation'!$J$121, {"<>correct"}))} -> 4 | K231: {=SUM(COUNTIF(Final_evaluation!$K$107:'Final_evaluation'!$K$121, {"<>correct"}))} -> 6 | L231: {=SUM(COUNTIF(Final_evaluation!$L$107:'Final_evaluation'!$L$121, {"<>correct"}))} -> 6 | M231: {=SUM(COUNTIF(Final_evaluation!$M$107:'Final_evaluation'!$M$121, {"<>correct"}))} -> 5 | N231: {=SUM(COUNTIF(Final_evaluation!$N$107:'Final_evaluation'!$N$121, {"<>correct"}))} -> 8 | O231: {=SUM(COUNTIF(Final_evaluation!$O$107:'Final_evaluation'!$O$121, {"<>correct"}))} -> 5 | P231: {=SUM(COUNTIF(Final_evaluation!$P$107:'Final_evaluation'!$P$121, {"<>correct"}))} -> 4 | Q231: {=SUM(COUNTIF(Final_evaluation!$Q$107:'Final_evaluation'!$Q$121, {"<>correct"}))} -> 4 | R231: {=SUM(COUNTIF(Final_evaluation!$R$107:'Final_evaluation'!$R$121, {"<>correct"}))} -> 7 | S231: {=SUM(COUNTIF(Final_evaluation!$S$107:'Final_evaluation'!$S$121, {"<>correct"}))} -> 3
A232: FP_numpy | B232: {=SUM(COUNTIF(Final_evaluation!$B$122:'Final_evaluation'!$B$136, {"<>correct"}))} -> 7 | C232: {=SUM(COUNTIF(Final_evaluation!$C$122:'Final_evaluation'!$C$136, {"<>correct"}))} -> 10 | D232: {=SUM(COUNTIF(Final_evaluation!$D$122:'Final_evaluation'!$D$136, {"<>correct"}))} -> 8 | E232: {=SUM(COUNTIF(Final_evaluation!$E$122:'Final_evaluation'!$E$136, {"<>correct"}))} -> 10 | F232: {=SUM(COUNTIF(Final_evaluation!$F$122:'Final_evaluation'!$F$136, {"<>correct"}))} -> 8 | G232: {=SUM(COUNTIF(Final_evaluation!$G$122:'Final_evaluation'!$G$136, {"<>correct"}))} -> 9 | H232: {=SUM(COUNTIF(Final_evaluation!$H$122:'Final_evaluation'!$H$136, {"<>correct"}))} -> 5 | I232: {=SUM(COUNTIF(Final_evaluation!$I$122:'Final_evaluation'!$I$136, {"<>correct"}))} -> 2 | J232: {=SUM(COUNTIF(Final_evaluation!$J$122:'Final_evaluation'!$J$136, {"<>correct"}))} -> 2 | K232: {=SUM(COUNTIF(Final_evaluation!$K$122:'Final_evaluation'!$K$136, {"<>correct"}))} -> 3 | L232: {=SUM(COUNTIF(Final_evaluation!$L$122:'Final_evaluation'!$L$136, {"<>correct"}))} -> 2 | M232: {=SUM(COUNTIF(Final_evaluation!$M$122:'Final_evaluation'!$M$136, {"<>correct"}))} -> 3 | N232: {=SUM(COUNTIF(Final_evaluation!$N$122:'Final_evaluation'!$N$136, {"<>correct"}))} -> 4 | O232: {=SUM(COUNTIF(Final_evaluation!$O$122:'Final_evaluation'!$O$136, {"<>correct"}))} -> 3 | P232: {=SUM(COUNTIF(Final_evaluation!$P$122:'Final_evaluation'!$P$136, {"<>correct"}))} -> 5 | Q232: {=SUM(COUNTIF(Final_evaluation!$Q$122:'Final_evaluation'!$Q$136, {"<>correct"}))} -> 4 | R232: {=SUM(COUNTIF(Final_evaluation!$R$122:'Final_evaluation'!$R$136, {"<>correct"}))} -> 5 | S232: {=SUM(COUNTIF(Final_evaluation!$S$122:'Final_evaluation'!$S$136, {"<>correct"}))} -> 4
A233: FN_numpy | B233: {=SUM(COUNTIF(Final_evaluation!$B$137:'Final_evaluation'!$B$151, {"<>correct"}))} -> 2 | C233: {=SUM(COUNTIF(Final_evaluation!$C$137:'Final_evaluation'!$C$151, {"<>correct"}))} -> 3 | D233: {=SUM(COUNTIF(Final_evaluation!$D$137:'Final_evaluation'!$D$151, {"<>correct"}))} -> 3 | E233: {=SUM(COUNTIF(Final_evaluation!$E$137:'Final_evaluation'!$E$151, {"<>correct"}))} -> 1 | F233: {=SUM(COUNTIF(Final_evaluation!$F$137:'Final_evaluation'!$F$151, {"<>correct"}))} -> 1 | G233: {=SUM(COUNTIF(Final_evaluation!$G$137:'Final_evaluation'!$G$151, {"<>correct"}))} -> 1 | H233: {=SUM(COUNTIF(Final_evaluation!$H$137:'Final_evaluation'!$H$151, {"<>correct"}))} -> 8 | I233: {=SUM(COUNTIF(Final_evaluation!$I$137:'Final_evaluation'!$I$151, {"<>correct"}))} -> 8 | J233: {=SUM(COUNTIF(Final_evaluation!$J$137:'Final_evaluation'!$J$151, {"<>correct"}))} -> 9 | K233: {=SUM(COUNTIF(Final_evaluation!$K$137:'Final_evaluation'!$K$151, {"<>correct"}))} -> 8 | L233: {=SUM(COUNTIF(Final_evaluation!$L$137:'Final_evaluation'!$L$151, {"<>correct"}))} -> 9 | M233: {=SUM(COUNTIF(Final_evaluation!$M$137:'Final_evaluation'!$M$151, {"<>correct"}))} -> 9 | N233: {=SUM(COUNTIF(Final_evaluation!$N$137:'Final_evaluation'!$N$151, {"<>correct"}))} -> 4 | O233: {=SUM(COUNTIF(Final_evaluation!$O$137:'Final_evaluation'!$O$151, {"<>correct"}))} -> 4 | P233: {=SUM(COUNTIF(Final_evaluation!$P$137:'Final_evaluation'!$P$151, {"<>correct"}))} -> 5 | Q233: {=SUM(COUNTIF(Final_evaluation!$Q$137:'Final_evaluation'!$Q$151, {"<>correct"}))} -> 4 | R233: {=SUM(COUNTIF(Final_evaluation!$R$137:'Final_evaluation'!$R$151, {"<>correct"}))} -> 4 | S233: {=SUM(COUNTIF(Final_evaluation!$S$137:'Final_evaluation'!$S$151, {"<>correct"}))} -> 4
A234: FP_other | B234: {=SUM(COUNTIF(Final_evaluation!$B$152:'Final_evaluation'!$B$167, {"<>correct"}))} -> 7 | C234: {=SUM(COUNTIF(Final_evaluation!$C$152:'Final_evaluation'!$C$167, {"<>correct"}))} -> 6 | D234: {=SUM(COUNTIF(Final_evaluation!$D$152:'Final_evaluation'!$D$167, {"<>correct"}))} -> 10 | E234: {=SUM(COUNTIF(Final_evaluation!$E$152:'Final_evaluation'!$E$167, {"<>correct"}))} -> 4 | F234: {=SUM(COUNTIF(Final_evaluation!$F$152:'Final_evaluation'!$F$167, {"<>correct"}))} -> 8 | G234: {=SUM(COUNTIF(Final_evaluation!$G$152:'Final_evaluation'!$G$167, {"<>correct"}))} -> 8 | H234: {=SUM(COUNTIF(Final_evaluation!$H$152:'Final_evaluation'!$H$167, {"<>correct"}))} -> 4 | I234: {=SUM(COUNTIF(Final_evaluation!$I$152:'Final_evaluation'!$I$167, {"<>correct"}))} -> 2 | J234: {=SUM(COUNTIF(Final_evaluation!$J$152:'Final_evaluation'!$J$167, {"<>correct"}))} -> 2 | K234: {=SUM(COUNTIF(Final_evaluation!$K$152:'Final_evaluation'!$K$167, {"<>correct"}))} -> 3 | L234: {=SUM(COUNTIF(Final_evaluation!$L$152:'Final_evaluation'!$L$167, {"<>correct"}))} -> 4 | M234: {=SUM(COUNTIF(Final_evaluation!$M$152:'Final_evaluation'!$M$167, {"<>correct"}))} -> 4 | N234: {=SUM(COUNTIF(Final_evaluation!$N$152:'Final_evaluation'!$N$167, {"<>correct"}))} -> 3 | O234: {=SUM(COUNTIF(Final_evaluation!$O$152:'Final_evaluation'!$O$167, {"<>correct"}))} -> 4 | P234: {=SUM(COUNTIF(Final_evaluation!$P$152:'Final_evaluation'!$P$167, {"<>correct"}))} -> 3 | Q234: {=SUM(COUNTIF(Final_evaluation!$Q$152:'Final_evaluation'!$Q$167, {"<>correct"}))} -> 3 | R234: {=SUM(COUNTIF(Final_evaluation!$R$152:'Final_evaluation'!$R$167, {"<>correct"}))} -> 4 | S234: {=SUM(COUNTIF(Final_evaluation!$S$152:'Final_evaluation'!$S$167, {"<>correct"}))} -> 3
A235: FN_other | B235: {=SUM(COUNTIF(Final_evaluation!$B$168:'Final_evaluation'!$B$183, {"<>correct"}))} -> 5 | C235: {=SUM(COUNTIF(Final_evaluation!$C$168:'Final_evaluation'!$C$183, {"<>correct"}))} -> 5 | D235: {=SUM(COUNTIF(Final_evaluation!$D$168:'Final_evaluation'!$D$183, {"<>correct"}))} -> 5 | E235: {=SUM(COUNTIF(Final_evaluation!$E$168:'Final_evaluation'!$E$183, {"<>correct"}))} -> 6 | F235: {=SUM(COUNTIF(Final_evaluation!$F$168:'Final_evaluation'!$F$183, {"<>correct"}))} -> 2 | G235: {=SUM(COUNTIF(Final_evaluation!$G$168:'Final_evaluation'!$G$183, {"<>correct"}))} -> 5 | H235: {=SUM(COUNTIF(Final_evaluation!$H$168:'Final_evaluation'!$H$183, {"<>correct"}))} -> 9 | I235: {=SUM(COUNTIF(Final_evaluation!$I$168:'Final_evaluation'!$I$183, {"<>correct"}))} -> 9 | J235: {=SUM(COUNTIF(Final_evaluation!$J$168:'Final_evaluation'!$J$183, {"<>correct"}))} -> 9 | K235: {=SUM(COUNTIF(Final_evaluation!$K$168:'Final_evaluation'!$K$183, {"<>correct"}))} -> 11 | L235: {=SUM(COUNTIF(Final_evaluation!$L$168:'Final_evaluation'!$L$183, {"<>correct"}))} -> 9 | M235: {=SUM(COUNTIF(Final_evaluation!$M$168:'Final_evaluation'!$M$183, {"<>correct"}))} -> 10 | N235: {=SUM(COUNTIF(Final_evaluation!$N$168:'Final_evaluation'!$N$183, {"<>correct"}))} -> 8 | O235: {=SUM(COUNTIF(Final_evaluation!$O$168:'Final_evaluation'!$O$183, {"<>correct"}))} -> 6 | P235: {=SUM(COUNTIF(Final_evaluation!$P$168:'Final_evaluation'!$P$183, {"<>correct"}))} -> 7 | Q235: {=SUM(COUNTIF(Final_evaluation!$Q$168:'Final_evaluation'!$Q$183, {"<>correct"}))} -> 7 | R235: {=SUM(COUNTIF(Final_evaluation!$R$168:'Final_evaluation'!$R$183, {"<>correct"}))} -> 7 | S235: {=SUM(COUNTIF(Final_evaluation!$S$168:'Final_evaluation'!$S$183, {"<>correct"}))} -> 6
A236: FP_NBspecific | B236: {=SUM(COUNTIF(Final_evaluation!$B$184:'Final_evaluation'!$B$203, {"<>correct"}))} -> 6 | C236: {=SUM(COUNTIF(Final_evaluation!$C$184:'Final_evaluation'!$C$203, {"<>correct"}))} -> 3 | D236: {=SUM(COUNTIF(Final_evaluation!$D$184:'Final_evaluation'!$D$203, {"<>correct"}))} -> 4 | E236: {=SUM(COUNTIF(Final_evaluation!$E$184:'Final_evaluation'!$E$203, {"<>correct"}))} -> 4 | F236: {=SUM(COUNTIF(Final_evaluation!$F$184:'Final_evaluation'!$F$203, {"<>correct"}))} -> 6 | G236: {=SUM(COUNTIF(Final_evaluation!$G$184:'Final_evaluation'!$G$203, {"<>correct"}))} -> 4 | H236: {=SUM(COUNTIF(Final_evaluation!$H$184:'Final_evaluation'!$H$203, {"<>correct"}))} -> 1 | I236: {=SUM(COUNTIF(Final_evaluation!$I$184:'Final_evaluation'!$I$203, {"<>correct"}))} -> 0 | J236: {=SUM(COUNTIF(Final_evaluation!$J$184:'Final_evaluation'!$J$203, {"<>correct"}))} -> 2 | K236: {=SUM(COUNTIF(Final_evaluation!$K$184:'Final_evaluation'!$K$203, {"<>correct"}))} -> 3 | L236: {=SUM(COUNTIF(Final_evaluation!$L$184:'Final_evaluation'!$L$203, {"<>correct"}))} -> 1 | M236: {=SUM(COUNTIF(Final_evaluation!$M$184:'Final_evaluation'!$M$203, {"<>correct"}))} -> 3 | N236: {=SUM(COUNTIF(Final_evaluation!$N$184:'Final_evaluation'!$N$203, {"<>correct"}))} -> 1 | O236: {=SUM(COUNTIF(Final_evaluation!$O$184:'Final_evaluation'!$O$203, {"<>correct"}))} -> 1 | P236: {=SUM(COUNTIF(Final_evaluation!$P$184:'Final_evaluation'!$P$203, {"<>correct"}))} -> 2 | Q236: {=SUM(COUNTIF(Final_evaluation!$Q$184:'Final_evaluation'!$Q$203, {"<>correct"}))} -> 1 | R236: {=SUM(COUNTIF(Final_evaluation!$R$184:'Final_evaluation'!$R$203, {"<>correct"}))} -> 0 | S236: {=SUM(COUNTIF(Final_evaluation!$S$184:'Final_evaluation'!$S$203, {"<>correct"}))} -> 2
A237: FN_NBspecific | B237: {=SUM(COUNTIF(Final_evaluation!$B$204:'Final_evaluation'!$B$223, {"<>correct"}))} -> 0 | C237: {=SUM(COUNTIF(Final_evaluation!$C$204:'Final_evaluation'!$C$223, {"<>correct"}))} -> 0 | D237: {=SUM(COUNTIF(Final_evaluation!$D$204:'Final_evaluation'!$D$223, {"<>correct"}))} -> 2 | E237: {=SUM(COUNTIF(Final_evaluation!$E$204:'Final_evaluation'!$E$223, {"<>correct"}))} -> 1 | F237: {=SUM(COUNTIF(Final_evaluation!$F$204:'Final_evaluation'!$F$223, {"<>correct"}))} -> 1 | G237: {=SUM(COUNTIF(Final_evaluation!$G$204:'Final_evaluation'!$G$223, {"<>correct"}))} -> 1 | H237: {=SUM(COUNTIF(Final_evaluation!$H$204:'Final_evaluation'!$H$223, {"<>correct"}))} -> 0 | I237: {=SUM(COUNTIF(Final_evaluation!$I$204:'Final_evaluation'!$I$223, {"<>correct"}))} -> 2 | J237: {=SUM(COUNTIF(Final_evaluation!$J$204:'Final_evaluation'!$J$223, {"<>correct"}))} -> 3 | K237: {=SUM(COUNTIF(Final_evaluation!$K$204:'Final_evaluation'!$K$223, {"<>correct"}))} -> 4 | L237: {=SUM(COUNTIF(Final_evaluation!$L$204:'Final_evaluation'!$L$223, {"<>correct"}))} -> 2 | M237: {=SUM(COUNTIF(Final_evaluation!$M$204:'Final_evaluation'!$M$223, {"<>correct"}))} -> 3 | N237: {=SUM(COUNTIF(Final_evaluation!$N$204:'Final_evaluation'!$N$223, {"<>correct"}))} -> 2 | O237: {=SUM(COUNTIF(Final_evaluation!$O$204:'Final_evaluation'!$O$223, {"<>correct"}))} -> 1 | P237: {=SUM(COUNTIF(Final_evaluation!$P$204:'Final_evaluation'!$P$223, {"<>correct"}))} -> 3 | Q237: {=SUM(COUNTIF(Final_evaluation!$Q$204:'Final_evaluation'!$Q$223, {"<>correct"}))} -> 2 | R237: {=SUM(COUNTIF(Final_evaluation!$R$204:'Final_evaluation'!$R$223, {"<>correct"}))} -> 4 | S237: {=SUM(COUNTIF(Final_evaluation!$S$204:'Final_evaluation'!$S$223, {"<>correct"}))} -> 1
A238: corrects_tensorflow | B238: {=SUM(COUNTIF($B$2:$B$31, {"correct"}))} -> 19 | C238: {=SUM(COUNTIF($C$2:$C$31, {"correct"}))} -> 18 | D238: {=SUM(COUNTIF($D$2:$D$31, {"correct"}))} -> 20 | E238: {=SUM(COUNTIF($E$2:$E$31, {"correct"}))} -> 21 | F238: {=SUM(COUNTIF($F$2:$F$31, {"correct"}))} -> 20 | G238: {=SUM(COUNTIF($G$2:$G$31, {"correct"}))} -> 18 | H238: {=SUM(COUNTIF($H$2:$H$31, {"correct"}))} -> 22 | I238: {=SUM(COUNTIF($I$2:$I$31, {"correct"}))} -> 28 | J238: {=SUM(COUNTIF($J$2:$J$31, {"correct"}))} -> 27 | K238: {=SUM(COUNTIF($K$2:$K$31, {"correct"}))} -> 25 | L238: {=SUM(COUNTIF($L$2:$L$31, {"correct"}))} -> 25 | M238: {=SUM(COUNTIF($M$2:$M$31, {"correct"}))} -> 24 | N238: {=SUM(COUNTIF($N$2:$N$31, {"correct"}))} -> 25 | O238: {=SUM(COUNTIF($O$2:$O$31, {"correct"}))} -> 25 | P238: {=SUM(COUNTIF($P$2:$P$31, {"correct"}))} -> 25 | Q238: {=SUM(COUNTIF($Q$2:$Q$31, {"correct"}))} -> 26 | R238: {=SUM(COUNTIF($R$2:$R$31, {"correct"}))} -> 24 | S238: {=SUM(COUNTIF($S$2:$S$31, {"correct"}))} -> 25
A239: acc_tensorflow | B239: =B238/ COUNTA($B$2:$B$31) -> 0.63333333 | C239: =C238/ COUNTA($C$2:$C$31) -> 0.6 | D239: =D238/ COUNTA($D$2:$D$31) -> 0.66666667 | E239: =E238/ COUNTA($E$2:$E$31) -> 0.7 | F239: =F238/ COUNTA($F$2:$F$31) -> 0.66666667 | G239: =G238/ COUNTA($G$2:$G$31) -> 0.6 | H239: =H238/ COUNTA($H$2:$H$31) -> 0.73333333 | I239: =I238/ COUNTA($I$2:$I$31) -> 0.93333333 | J239: =J238/ COUNTA($J$2:$J$31) -> 0.9 | K239: =K238/ COUNTA($K$2:$K$31) -> 0.83333333 | L239: =L238/ COUNTA($L$2:$L$31) -> 0.83333333 | M239: =M238/ COUNTA($M$2:$M$31) -> 0.8 | N239: =N238/ COUNTA($N$2:$N$31) -> 0.83333333 | O239: =O238/ COUNTA($O$2:$O$31) -> 0.83333333 | P239: =P238/ COUNTA($P$2:$P$31) -> 0.83333333 | Q239: =Q238/ COUNTA($Q$2:$Q$31) -> 0.86666667 | R239: =R238/ COUNTA($R$2:$R$31) -> 0.8 | S239: =S238/ COUNTA($S$2:$S$31) -> 0.83333333
A240: corrects_torch | B240: {=SUM(COUNTIF($B$32:$B$61, {"correct"}))} -> 16 | C240: {=SUM(COUNTIF($C$32:$C$61, {"correct"}))} -> 18 | D240: {=SUM(COUNTIF($D$32:$D$61, {"correct"}))} -> 21 | E240: {=SUM(COUNTIF($E$32:$E$61, {"correct"}))} -> 17 | F240: {=SUM(COUNTIF($F$32:$F$61, {"correct"}))} -> 20 | G240: {=SUM(COUNTIF($G$32:$G$61, {"correct"}))} -> 20 | H240: {=SUM(COUNTIF($H$32:$H$61, {"correct"}))} -> 16 | I240: {=SUM(COUNTIF($I$32:$I$61, {"correct"}))} -> 18 | J240: {=SUM(COUNTIF($J$32:$J$61, {"correct"}))} -> 15 | K240: {=SUM(COUNTIF($K$32:$K$61, {"correct"}))} -> 15 | L240: {=SUM(COUNTIF($L$32:$L$61, {"correct"}))} -> 16 | M240: {=SUM(COUNTIF($M$32:$M$61, {"correct"}))} -> 18 | N240: {=SUM(COUNTIF($N$32:$N$61, {"correct"}))} -> 22 | O240: {=SUM(COUNTIF($O$32:$O$61, {"correct"}))} -> 22 | P240: {=SUM(COUNTIF($P$32:$P$61, {"correct"}))} -> 23 | Q240: {=SUM(COUNTIF($Q$32:$Q$61, {"correct"}))} -> 22 | R240: {=SUM(COUNTIF($R$32:$R$61, {"correct"}))} -> 20 | S240: {=SUM(COUNTIF($S$32:$S$61, {"correct"}))} -> 22
A241: acc_torch | B241: =B240/ COUNTA($B$32:$B$61) -> 0.53333333 | C241: =C240/ COUNTA($C$32:$C$61) -> 0.6 | D241: =D240/ COUNTA($D$32:$D$61) -> 0.7 | E241: =E240/ COUNTA($E$32:$E$61) -> 0.56666667 | F241: =F240/ COUNTA($F$32:$F$61) -> 0.66666667 | G241: =G240/ COUNTA($G$32:$G$61) -> 0.66666667 | H241: =H240/ COUNTA($H$32:$H$61) -> 0.53333333 | I241: =I240/ COUNTA($I$32:$I$61) -> 0.6 | J241: =J240/ COUNTA($J$32:$J$61) -> 0.5 | K241: =K240/ COUNTA($K$32:$K$61) -> 0.5 | L241: =L240/ COUNTA($L$32:$L$61) -> 0.53333333 | M241: =M240/ COUNTA($M$32:$M$61) -> 0.6 | N241: =N240/ COUNTA($N$32:$N$61) -> 0.73333333 | O241: =O240/ COUNTA($O$32:$O$61) -> 0.73333333 | P241: =P240/ COUNTA($P$32:$P$61) -> 0.76666667 | Q241: =Q240/ COUNTA($Q$32:$Q$61) -> 0.73333333 | R241: =R240/ COUNTA($R$32:$R$61) -> 0.66666667 | S241: =S240/ COUNTA($S$32:$S$61) -> 0.73333333
A242: corrects_sklearn | B242: {=SUM(COUNTIF($B$62:$B$91, {"correct"}))} -> 20 | C242: {=SUM(COUNTIF($C$62:$C$91, {"correct"}))} -> 26 | D242: {=SUM(COUNTIF($D$62:$D$91, {"correct"}))} -> 27 | E242: {=SUM(COUNTIF($E$62:$E$91, {"correct"}))} -> 25 | F242: {=SUM(COUNTIF($F$62:$F$91, {"correct"}))} -> 25 | G242: {=SUM(COUNTIF($G$62:$G$91, {"correct"}))} -> 24 | H242: {=SUM(COUNTIF($H$62:$H$91, {"correct"}))} -> 22 | I242: {=SUM(COUNTIF($I$62:$I$91, {"correct"}))} -> 25 | J242: {=SUM(COUNTIF($J$62:$J$91, {"correct"}))} -> 25 | K242: {=SUM(COUNTIF($K$62:$K$91, {"correct"}))} -> 25 | L242: {=SUM(COUNTIF($L$62:$L$91, {"correct"}))} -> 26 | M242: {=SUM(COUNTIF($M$62:$M$91, {"correct"}))} -> 24 | N242: {=SUM(COUNTIF($N$62:$N$91, {"correct"}))} -> 25 | O242: {=SUM(COUNTIF($O$62:$O$91, {"correct"}))} -> 26 | P242: {=SUM(COUNTIF($P$62:$P$91, {"correct"}))} -> 28 | Q242: {=SUM(COUNTIF($Q$62:$Q$91, {"correct"}))} -> 28 | R242: {=SUM(COUNTIF($R$62:$R$91, {"correct"}))} -> 29 | S242: {=SUM(COUNTIF($S$62:$S$91, {"correct"}))} -> 27
A243: acc_sklearn | B243: =B242/ COUNTA($B$62:$B$91) -> 0.66666667 | C243: =C242/ COUNTA($C$62:$C$91) -> 0.86666667 | D243: =D242/ COUNTA($D$62:$D$91) -> 0.9 | E243: =E242/ COUNTA($E$62:$E$91) -> 0.83333333 | F243: =F242/ COUNTA($F$62:$F$91) -> 0.83333333 | G243: =G242/ COUNTA($G$62:$G$91) -> 0.8 | H243: =H242/ COUNTA($H$62:$H$91) -> 0.73333333 | I243: =I242/ COUNTA($I$62:$I$91) -> 0.83333333 | J243: =J242/ COUNTA($J$62:$J$91) -> 0.83333333 | K243: =K242/ COUNTA($K$62:$K$91) -> 0.83333333 | L243: =L242/ COUNTA($L$62:$L$91) -> 0.86666667 | M243: =M242/ COUNTA($M$62:$M$91) -> 0.8 | N243: =N242/ COUNTA($N$62:$N$91) -> 0.83333333 | O243: =O242/ COUNTA($O$62:$O$91) -> 0.86666667 | P243: =P242/ COUNTA($P$62:$P$91) -> 0.93333333 | Q243: =Q242/ COUNTA($Q$62:$Q$91) -> 0.93333333 | R243: =R242/ COUNTA($R$62:$R$91) -> 0.96666667 | S243: =S242/ COUNTA($S$62:$S$91) -> 0.9
A244: corrects_pandas | B244: {=SUM(COUNTIF($B$92:$B$121, {"correct"}))} -> 20 | C244: {=SUM(COUNTIF($C$92:$C$121, {"correct"}))} -> 26 | D244: {=SUM(COUNTIF($D$92:$D$121, {"correct"}))} -> 23 | E244: {=SUM(COUNTIF($E$92:$E$121, {"correct"}))} -> 26 | F244: {=SUM(COUNTIF($F$92:$F$121, {"correct"}))} -> 24 | G244: {=SUM(COUNTIF($G$92:$G$121, {"correct"}))} -> 24 | H244: {=SUM(COUNTIF($H$92:$H$121, {"correct"}))} -> 20 | I244: {=SUM(COUNTIF($I$92:$I$121, {"correct"}))} -> 23 | J244: {=SUM(COUNTIF($J$92:$J$121, {"correct"}))} -> 24 | K244: {=SUM(COUNTIF($K$92:$K$121, {"correct"}))} -> 21 | L244: {=SUM(COUNTIF($L$92:$L$121, {"correct"}))} -> 21 | M244: {=SUM(COUNTIF($M$92:$M$121, {"correct"}))} -> 19 | N244: {=SUM(COUNTIF($N$92:$N$121, {"correct"}))} -> 17 | O244: {=SUM(COUNTIF($O$92:$O$121, {"correct"}))} -> 23 | P244: {=SUM(COUNTIF($P$92:$P$121, {"correct"}))} -> 24 | Q244: {=SUM(COUNTIF($Q$92:$Q$121, {"correct"}))} -> 24 | R244: {=SUM(COUNTIF($R$92:$R$121, {"correct"}))} -> 20 | S244: {=SUM(COUNTIF($S$92:$S$121, {"correct"}))} -> 26
A245: acc_pandas | B245: =B244/ COUNTA( $B$92:$B$121) -> 0.66666667 | C245: =C244/ COUNTA( $C$92:$C$121) -> 0.86666667 | D245: =D244/ COUNTA( $D$92:$D$121) -> 0.76666667 | E245: =E244/ COUNTA( $E$92:$E$121) -> 0.86666667 | F245: =F244/ COUNTA( $F$92:$F$121) -> 0.8 | G245: =G244/ COUNTA( $G$92:$G$121) -> 0.8 | H245: =H244/ COUNTA( $H$92:$H$121) -> 0.66666667 | I245: =I244/ COUNTA( $I$92:$I$121) -> 0.76666667 | J245: =J244/ COUNTA( $J$92:$J$121) -> 0.8 | K245: =K244/ COUNTA( $K$92:$K$121) -> 0.7 | L245: =L244/ COUNTA( $L$92:$L$121) -> 0.7 | M245: =M244/ COUNTA( $M$92:$M$121) -> 0.63333333 | N245: =N244/ COUNTA( $N$92:$N$121) -> 0.56666667 | O245: =O244/ COUNTA( $O$92:$O$121) -> 0.76666667 | P245: =P244/ COUNTA( $P$92:$P$121) -> 0.8 | Q245: =Q244/ COUNTA( $Q$92:$Q$121) -> 0.8 | R245: =R244/ COUNTA( $R$92:$R$121) -> 0.66666667 | S245: =S244/ COUNTA( $S$92:$S$121) -> 0.86666667
A246: corrects_numpy | B246: {=SUM(COUNTIF($B$122:$B$151, {"correct"}))} -> 21 | C246: {=SUM(COUNTIF($C$122:$C$151, {"correct"}))} -> 17 | D246: {=SUM(COUNTIF($D$122:$D$151, {"correct"}))} -> 19 | E246: {=SUM(COUNTIF($E$122:$E$151, {"correct"}))} -> 19 | F246: {=SUM(COUNTIF($F$122:$F$151, {"correct"}))} -> 21 | G246: {=SUM(COUNTIF($G$122:$G$151, {"correct"}))} -> 20 | H246: {=SUM(COUNTIF($H$122:$H$151, {"correct"}))} -> 17 | I246: {=SUM(COUNTIF($I$122:$I$151, {"correct"}))} -> 20 | J246: {=SUM(COUNTIF($J$122:$J$151, {"correct"}))} -> 19 | K246: {=SUM(COUNTIF($K$122:$K$151, {"correct"}))} -> 19 | L246: {=SUM(COUNTIF($L$122:$L$151, {"correct"}))} -> 19 | M246: {=SUM(COUNTIF($M$122:$M$151, {"correct"}))} -> 18 | N246: {=SUM(COUNTIF($N$122:$N$151, {"correct"}))} -> 22 | O246: {=SUM(COUNTIF($O$122:$O$151, {"correct"}))} -> 23 | P246: {=SUM(COUNTIF($P$122:$P$151, {"correct"}))} -> 20 | Q246: {=SUM(COUNTIF($Q$122:$Q$151, {"correct"}))} -> 22 | R246: {=SUM(COUNTIF($R$122:$R$151, {"correct"}))} -> 21 | S246: {=SUM(COUNTIF($S$122:$S$151, {"correct"}))} -> 22
A247: acc_numpy | B247: =B246/ COUNTA( $B$122:$B$151) -> 0.7 | C247: =C246/ COUNTA( $C$122:$C$151) -> 0.56666667 | D247: =D246/ COUNTA( $D$122:$D$151) -> 0.63333333 | E247: =E246/ COUNTA( $E$122:$E$151) -> 0.63333333 | F247: =F246/ COUNTA( $F$122:$F$151) -> 0.7 | G247: =G246/ COUNTA( $G$122:$G$151) -> 0.66666667 | H247: =H246/ COUNTA( $H$122:$H$151) -> 0.56666667 | I247: =I246/ COUNTA( $I$122:$I$151) -> 0.66666667 | J247: =J246/ COUNTA( $J$122:$J$151) -> 0.63333333 | K247: =K246/ COUNTA( $K$122:$K$151) -> 0.63333333 | L247: =L246/ COUNTA( $L$122:$L$151) -> 0.63333333 | M247: =M246/ COUNTA( $M$122:$M$151) -> 0.6 | N247: =N246/ COUNTA( $N$122:$N$151) -> 0.73333333 | O247: =O246/ COUNTA( $O$122:$O$151) -> 0.76666667 | P247: =P246/ COUNTA( $P$122:$P$151) -> 0.66666667 | Q247: =Q246/ COUNTA( $Q$122:$Q$151) -> 0.73333333 | R247: =R246/ COUNTA( $R$122:$R$151) -> 0.7 | S247: =S246/ COUNTA( $S$122:$S$151) -> 0.73333333
A248: corrects_other | B248: {=SUM(COUNTIF($B$152:$B$183, {"correct"}))} -> 20 | C248: {=SUM(COUNTIF($C$152:$C$183, {"correct"}))} -> 21 | D248: {=SUM(COUNTIF($D$152:$D$183, {"correct"}))} -> 17 | E248: {=SUM(COUNTIF($E$152:$E$183, {"correct"}))} -> 22 | F248: {=SUM(COUNTIF($F$152:$F$183, {"correct"}))} -> 22 | G248: {=SUM(COUNTIF($G$152:$G$183, {"correct"}))} -> 19 | H248: {=SUM(COUNTIF($H$152:$H$183, {"correct"}))} -> 19 | I248: {=SUM(COUNTIF($I$152:$I$183, {"correct"}))} -> 21 | J248: {=SUM(COUNTIF($J$152:$J$183, {"correct"}))} -> 21 | K248: {=SUM(COUNTIF($K$152:$K$183, {"correct"}))} -> 18 | L248: {=SUM(COUNTIF($L$152:$L$183, {"correct"}))} -> 19 | M248: {=SUM(COUNTIF($M$152:$M$183, {"correct"}))} -> 18 | N248: {=SUM(COUNTIF($N$152:$N$183, {"correct"}))} -> 21 | O248: {=SUM(COUNTIF($O$152:$O$183, {"correct"}))} -> 22 | P248: {=SUM(COUNTIF($P$152:$P$183, {"correct"}))} -> 22 | Q248: {=SUM(COUNTIF($Q$152:$Q$183, {"correct"}))} -> 22 | R248: {=SUM(COUNTIF($R$152:$R$183, {"correct"}))} -> 21 | S248: {=SUM(COUNTIF($S$152:$S$183, {"correct"}))} -> 23
A249: acc_other | B249: =B248/ COUNTA( $B$152:$B$183) -> 0.625 | C249: =C248/ COUNTA( $C$152:$C$183) -> 0.65625 | D249: =D248/ COUNTA( $D$152:$D$183) -> 0.53125 | E249: =E248/ COUNTA( $E$152:$E$183) -> 0.6875 | F249: =F248/ COUNTA( $F$152:$F$183) -> 0.6875 | G249: =G248/ COUNTA( $G$152:$G$183) -> 0.59375 | H249: =H248/ COUNTA( $H$152:$H$183) -> 0.59375 | I249: =I248/ COUNTA( $I$152:$I$183) -> 0.65625 | J249: =J248/ COUNTA( $J$152:$J$183) -> 0.65625 | K249: =K248/ COUNTA( $K$152:$K$183) -> 0.5625 | L249: =L248/ COUNTA( $L$152:$L$183) -> 0.59375 | M249: =M248/ COUNTA( $M$152:$M$183) -> 0.5625 | N249: =N248/ COUNTA( $N$152:$N$183) -> 0.65625 | O249: =O248/ COUNTA( $O$152:$O$183) -> 0.6875 | P249: =P248/ COUNTA( $P$152:$P$183) -> 0.6875 | Q249: =Q248/ COUNTA( $Q$152:$Q$183) -> 0.6875 | R249: =R248/ COUNTA( $R$152:$R$183) -> 0.65625 | S249: =S248/ COUNTA( $S$152:$S$183) -> 0.71875
A250: corrects_nbspecific | B250: {=SUM(COUNTIF($B$184:$B$223, {"correct"}))} -> 34 | C250: {=SUM(COUNTIF($C$184:$C$223, {"correct"}))} -> 37 | D250: {=SUM(COUNTIF($D$184:$D$223, {"correct"}))} -> 34 | E250: {=SUM(COUNTIF($E$184:$E$223, {"correct"}))} -> 35 | F250: {=SUM(COUNTIF($F$184:$F$223, {"correct"}))} -> 33 | G250: {=SUM(COUNTIF($G$184:$G$223, {"correct"}))} -> 35 | H250: {=SUM(COUNTIF($H$184:$H$223, {"correct"}))} -> 39 | I250: {=SUM(COUNTIF($I$184:$I$223, {"correct"}))} -> 38 | J250: {=SUM(COUNTIF($J$184:$J$223, {"correct"}))} -> 35 | K250: {=SUM(COUNTIF($K$184:$K$223, {"correct"}))} -> 33 | L250: {=SUM(COUNTIF($L$184:$L$223, {"correct"}))} -> 37 | M250: {=SUM(COUNTIF($M$184:$M$223, {"correct"}))} -> 34 | N250: {=SUM(COUNTIF($N$184:$N$223, {"correct"}))} -> 37 | O250: {=SUM(COUNTIF($O$184:$O$223, {"correct"}))} -> 38 | P250: {=SUM(COUNTIF($P$184:$P$223, {"correct"}))} -> 35 | Q250: {=SUM(COUNTIF($Q$184:$Q$223, {"correct"}))} -> 37 | R250: {=SUM(COUNTIF($R$184:$R$223, {"correct"}))} -> 36 | S250: {=SUM(COUNTIF($S$184:$S$223, {"correct"}))} -> 37
...

Sheet Results_summary
A1: Crash detection and diagnosis results | T1: Overall results
T2: LLM | U2: Crash detection
A3: gemini 2.5 flash | B3: Count | C3: FP-RT | D3: FP+RT | E3: FN-RT | F3: FN+RT | G3: FPR-RT | H3: FPR+RT | I3: FNR-RT | J3: FNR+RT | K3: Prec-RT | L3: Prec+RT | M3: Rec-RT | N3: Rec+RT | O3: F1-RT | P3: F1+RT | Q3: Acc-RT | R3: Acc+RT | U3: Prec-RT | V3: Prec+RT | W3: Rec-RT | X3: Rec+RT | Y3: F1-RT | Z3: F1+RT | AA3: Acc-RT | AB3: Acc+RT
A4: tensorflow | B4: 30 | C4: =Final_evaluation!$B$224 -> 9 | D4: =Final_evaluation!$C$224 -> 11 | E4: =Final_evaluation!$B$225 -> 2 | F4: =Final_evaluation!$C$225 -> 1 | G4: =C4/B4 -> 0.3 | H4: =D4/B4 -> 0.36666667 | I4: =E4/B4 -> 0.066666667 | J4: =F4/B4 -> 0.033333333 | K4: =($B$4/2-$E$4)/(($B$4/2-$E$4)+$C$4) -> 0.59090909 | L4: =($B$4/2-$F$4)/(($B$4/2-$F$4)+$D$4) -> 0.56 | M4: =($B$4/2-$E$4)/($B$4/2) -> 0.86666667 | N4: =($B$4/2-$F$4)/($B$4/2) -> 0.93333333 | O4: =$K$4*$M$4*2/($K$4+$M$4) -> 0.7027027 | P4: =$L$4*$N$4*2/($L$4+$N$4) -> 0.7 | Q4: =($B$4-$C$4-$E$4)/$B$4 -> 0.63333333 | R4: =($B$4-$D$4-$F$4)/$B$4 -> 0.6 | T4: LLM - gemini | U4: =($B$11/2-$E$11)/(($B$11/2-$E$11)+$C$11) -> 0.63829787 | V4: =($B$11/2-$F$11)/(($B$11/2-$F$11)+$D$11) -> 0.67808219 | W4: =($B$11/2-$E$11)/($B$11/2) -> 0.81081081 | X4: =($B$11/2-$F$11)/($B$11/2) -> 0.89189189 | Y4: =$K$11*$M$11*2/($K$11+$M$11) -> 0.71428571 | Z4: =$L$11*$N$11*2/($L$11+$N$11) -> 0.77042802 | AA4: =($B$11-$C$11-$E$11)/$B$11 -> 0.67567568 | AB4: =($B$11-$D$11-$F$11)/$B$11 -> 0.73423423
A5: torch | B5: 30 | C5: =Final_evaluation!$B$226 -> 10 | D5: =Final_evaluation!$C$226 -> 10 | E5: =Final_evaluation!$B$227 -> 4 | F5: =Final_evaluation!$C$227 -> 2 | G5: =C5/B5 -> 0.33333333 | H5: =D5/B5 -> 0.33333333 | I5: =E5/B5 -> 0.13333333 | J5: =F5/B5 -> 0.066666667 | K5: =($B$5/2-$E$5)/(($B$5/2-$E$5)+$C$5) -> 0.52380952 | L5: =($B$5/2-$F$5)/(($B$5/2-$F$5)+$D$5) -> 0.56521739 | M5: =($B$5/2-$E$5)/($B$5/2) -> 0.73333333 | N5: =($B$5/2-$F$5)/($B$5/2) -> 0.86666667 | O5: =$K$5*$M$5*2/($K$5+$M$5) -> 0.61111111 | P5: =$L$5*$N$5*2/($L$5+$N$5) -> 0.68421053 | Q5: =($B$5-$C$5-$E$5)/$B$5 -> 0.53333333 | R5: =($B$5-$D$5-$F$5)/$B$5 -> 0.6 | T5: LLM - qwen | U5: =($B$22/2-$E$22)/(($B$22/2-$E$22)+$C$22) -> 0.7244898 | V5: =($B$22/2-$F$22)/(($B$22/2-$F$22)+$D$22) -> 0.86046512 | W5: =($B$22/2-$E$22)/($B$22/2) -> 0.63963964 | X5: =($B$22/2-$F$22)/($B$22/2) -> 0.66666667 | Y5: =$K$22*$M$22*2/($K$22+$M$22) -> 0.67942584 | Z5: =$L$22*$N$22*2/($L$22+$N$22) -> 0.75126904 | AA5: =($B$22-$C$22-$E$22)/$B$22 -> 0.6981982 | AB5: =($B$22-$D$22-$F$22)/$B$22 -> 0.77927928
A6: sklearn | B6: 30 | C6: =Final_evaluation!$B$228 -> 5 | D6: =Final_evaluation!$C$228 -> 4 | E6: =Final_evaluation!$B$229 -> 5 | F6: =Final_evaluation!$C$229 -> 0 | G6: =C6/B6 -> 0.16666667 | H6: =D6/B6 -> 0.13333333 | I6: =E6/B6 -> 0.16666667 | J6: =F6/B6 -> 0 | K6: =($B$6/2-$E$6)/(($B$6/2-$E$6)+$C$6) -> 0.66666667 | L6: =($B$6/2-$F$6)/(($B$6/2-$F$6)+$D$6) -> 0.78947368 | M6: =($B$6/2-$E$6)/($B$6/2) -> 0.66666667 | N6: =($B$6/2-$F$6)/($B$6/2) -> 1 | O6: =$K$6*$M$6*2/($K$6+$M$6) -> 0.66666667 | P6: =$L$6*$N$6*2/($L$6+$N$6) -> 0.88235294 | Q6: =($B$6-$C$6-$E$6)/$B$6 -> 0.66666667 | R6: =($B$6-$D$6-$F$6)/$B$6 -> 0.86666667 | T6: LLM - gpt5 | U6: =($B$33/2-$E$33)/(($B$33/2-$E$33)+$C$33) -> 0.79 | V6: =($B$33/2-$F$33)/(($B$33/2-$F$33)+$D$33) -> 0.81481481 | W6: =($B$33/2-$E$33)/($B$33/2) -> 0.71171171 | X6: =($B$33/2-$F$33)/($B$33/2) -> 0.79279279 | Y6: =$K$33*$M$33*2/($K$33+$M$33) -> 0.74881517 | Z6: =$L$33*$N$33*2/($L$33+$N$33) -> 0.80365297 | AA6: =($B$33-$C$33-$E$33)/$B$33 -> 0.76126126 | AB6: =($B$33-$D$33-$F$33)/$B$33 -> 0.80630631
A7: pandas | B7: 30 | C7: =Final_evaluation!$B$230 -> 7 | D7: =Final_evaluation!$C$230 -> 3 | E7: =Final_evaluation!$B$231 -> 3 | F7: =Final_evaluation!$C$231 -> 1 | G7: =C7/B7 -> 0.23333333 | H7: =D7/B7 -> 0.1 | I7: =E7/B7 -> 0.1 | J7: =F7/B7 -> 0.033333333 | K7: =($B$7/2-$E$7)/(($B$7/2-$E$7)+$C$7) -> 0.63157895 | L7: =($B$7/2-$F$7)/(($B$7/2-$F$7)+$D$7) -> 0.82352941 | M7: =($B$7/2-$E$7)/($B$7/2) -> 0.8 | N7: =($B$7/2-$F$7)/($B$7/2) -> 0.93333333 | O7: =$K$7*$M$7*2/($K$7+$M$7) -> 0.70588235 | P7: =$L$7*$N$7*2/($L$7+$N$7) -> 0.875 | Q7: =($B$7-$C$7-$E$7)/$B$7 -> 0.66666667 | R7: =($B$7-$D$7-$F$7)/$B$7 -> 0.86666667
A8: numpy | B8: 30 | C8: =Final_evaluation!$B$232 -> 7 | D8: =Final_evaluation!$C$232 -> 10 | E8: =Final_evaluation!$B$233 -> 2 | F8: =Final_evaluation!$C$233 -> 3 | G8: =C8/B8 -> 0.23333333 | H8: =D8/B8 -> 0.33333333 | I8: =E8/B8 -> 0.066666667 | J8: =F8/B8 -> 0.1 | K8: =($B$8/2-$E$8)/(($B$8/2-$E$8)+$C$8) -> 0.65 | L8: =($B$8/2-$F$8)/(($B$8/2-$F$8)+$D$8) -> 0.54545455 | M8: =($B$8/2-$E$8)/($B$8/2) -> 0.86666667 | N8: =($B$8/2-$F$8)/($B$8/2) -> 0.8 | O8: =$K$8*$M$8*2/($K$8+$M$8) -> 0.74285714 | P8: =$L$8*$N$8*2/($L$8+$N$8) -> 0.64864865 | Q8: =($B$8-$C$8-$E$8)/$B$8 -> 0.7 | R8: =($B$8-$D$8-$F$8)/$B$8 -> 0.56666667 | T8: Diff | V8: Prec | X8: Rec | Z8: F1 | AB8: Acc
A9: other | B9: 32 | C9: =Final_evaluation!$B$234 -> 7 | D9: =Final_evaluation!$C$234 -> 6 | E9: =Final_evaluation!$B$235 -> 5 | F9: =Final_evaluation!$C$235 -> 5 | G9: =C9/B9 -> 0.21875 | H9: =D9/B9 -> 0.1875 | I9: =E9/B9 -> 0.15625 | J9: =F9/B9 -> 0.15625 | K9: =($B$9/2-$E$9)/(($B$9/2-$E$9)+$C$9) -> 0.61111111 | L9: =($B$9/2-$F$9)/(($B$9/2-$F$9)+$D$9) -> 0.64705882 | M9: =($B$9/2-$E$9)/($B$9/2) -> 0.6875 | N9: =($B$9/2-$F$9)/($B$9/2) -> 0.6875 | O9: =$K$9*$M$9*2/($K$9+$M$9) -> 0.64705882 | P9: =$L$9*$N$9*2/($L$9+$N$9) -> 0.66666667 | Q9: =($B$9-$C$9-$E$9)/$B$9 -> 0.625 | R9: =($B$9-$D$9-$F$9)/$B$9 -> 0.65625 | T9: LLM - gemini | V9: =V4-U4 -> 0.039784319 | X9: =X4-W4 -> 0.081081081 | Z9: =Z4-Y4 -> 0.056142301 | AB9: =AB4-AA4 -> 0.058558559
A10: NBspecific | B10: 40 | C10: =Final_evaluation!$B$236 -> 6 | D10: =Final_evaluation!$C$236 -> 3 | E10: =Final_evaluation!$B$237 -> 0 | F10: =Final_evaluation!$C$237 -> 0 | G10: =C10/B10 -> 0.15 | H10: =D10/B10 -> 0.075 | I10: =E10/B10 -> 0 | J10: =F10/B10 -> 0 | K10: =($B$10/2-$E$10)/(($B$10/2-$E$10)+$C$10) -> 0.76923077 | L10: =($B$10/2-$F$10)/(($B$10/2-$F$10)+$D$10) -> 0.86956522 | M10: =($B$10/2-$E$10)/($B$10/2) -> 1 | N10: =($B$10/2-$F$10)/($B$10/2) -> 1 | O10: =$K$10*$M$10*2/($K$10+$M$10) -> 0.86956522 | P10: =$L$10*$N$10*2/($L$10+$N$10) -> 0.93023256 | Q10: =($B$10-$C$10-$E$10)/$B$10 -> 0.85 | R10: =($B$10-$D$10-$F$10)/$B$10 -> 0.925 | T10: LLM - qwen | V10: =V5-U5 -> 0.13597532 | X10: =X5-W5 -> 0.027027027 | Z10: =Z5-Y5 -> 0.071843198 | AB10: =AB5-AA5 -> 0.081081081
A11: total | B11: =SUM(B4:B10) -> 222 | C11: =SUM(C4:C10) -> 51 | D11: =SUM(D4:D10) -> 47 | E11: =SUM(E4:E10) -> 21 | F11: =SUM(F4:F10) -> 12 | G11: =C11/B11 -> 0.22972973 | H11: =D11/B11 -> 0.21171171 | I11: =E11/B11 -> 0.094594595 | J11: =F11/B11 -> 0.054054054 | K11: =($B$11/2-$E$11)/(($B$11/2-$E$11)+$C$11) -> 0.63829787 | L11: =($B$11/2-$F$11)/(($B$11/2-$F$11)+$D$11) -> 0.67808219 | M11: =($B$11/2-$E$11)/($B$11/2) -> 0.81081081 | N11: =($B$11/2-$F$11)/($B$11/2) -> 0.89189189 | O11: =$K$11*$M$11*2/($K$11+$M$11) -> 0.71428571 | P11: =$L$11*$N$11*2/($L$11+$N$11) -> 0.77042802 | Q11: =($B$11-$C$11-$E$11)/$B$11 -> 0.67567568 | R11: =($B$11-$D$11-$F$11)/$B$11 -> 0.73423423 | T11: LLM - gpt5 | V11: =V6-U6 -> 0.024814815 | X11: =X6-W6 -> 0.081081081 | Z11: =Z6-Y6 -> 0.054837802 | AB11: =AB6-AA6 -> 0.045045045
T13: LLM | U13: Runtime information ablation study
A14: qwen 2.5 32b instruct | B14: Count | C14: FP-RT | D14: FP+RT | E14: FN-RT | F14: FN+RT | G14: FPR-RT | H14: FPR+RT | I14: FNR-RT | J14: FNR+RT | K14: Prec-RT | L14: Prec+RT | M14: Rec-RT | N14: Rec+RT | O14: F1-RT | P14: F1+RT | Q14: Acc-RT | R14: Acc+RT | U14: F1+RT | V14: F1+RT-S | W14: F1+RT-V | X14: F1+RT-R | Y14: Acc+RT | Z14: Acc+RT-S | AA14: Acc+RT-V | AB14: Acc+RT-R
A15: tensorflow | B15: 30 | C15: =Final_evaluation!$H$224 -> 5 | D15: =Final_evaluation!$I$224 -> 0 | E15: =Final_evaluation!$H$225 -> 3 | F15: =Final_evaluation!$I$225 -> 2 | G15: =C15/B15 -> 0.16666667 | H15: =D15/B15 -> 0 | I15: =E15/B15 -> 0.1 | J15: =F15/B15 -> 0.066666667 | K15: =($B$15/2-$E$15)/(($B$15/2-$E$15)+$C$15) -> 0.70588235 | L15: =($B$15/2-$F$15)/(($B$15/2-$F$15)+$D$15) -> 1 | M15: =($B$15/2-$E$15)/($B$15/2) -> 0.8 | N15: =($B$15/2-$F$15)/($B$15/2) -> 0.86666667 | O15: =$K$15*$M$15*2/($K$15+$M$15) -> 0.75 | P15: =$L$15*$N$15*2/($L$15+$N$15) -> 0.92857143 | Q15: =($B$15-$C$15-$E$15)/$B$15 -> 0.73333333 | R15: =($B$15-$D$15-$F$15)/$B$15 -> 0.93333333 | T15: LLM - gemini | U15: =S45 -> 0.77042802 | V15: =T45 -> 0.77290837 | W15: =U45 -> 0.76734694 | X15: =V45 -> 0.7578125 | Y15: =W45 -> 0.73423423 | Z15: =X45 -> 0.74324324 | AA15: =Y45 -> 0.74324324 | AB15: =Z45 -> 0.72072072
A16: torch | B16: 30 | C16: =Final_evaluation!$H$226 -> 5 | D16: =Final_evaluation!$I$226 -> 5 | E16: =Final_evaluation!$H$227 -> 9 | F16: =Final_evaluation!$I$227 -> 7 | G16: =C16/B16 -> 0.16666667 | H16: =D16/B16 -> 0.16666667 | I16: =E16/B16 -> 0.3 | J16: =F16/B16 -> 0.23333333 | K16: =($B$16/2-$E$16)/(($B$16/2-$E$16)+$C$16) -> 0.54545455 | L16: =($B$16/2-$F$16)/(($B$16/2-$F$16)+$D$16) -> 0.61538462 | M16: =($B$16/2-$E$16)/($B$16/2) -> 0.4 | N16: =($B$16/2-$F$16)/($B$16/2) -> 0.53333333 | O16: =$K$16*$M$16*2/($K$16+$M$16) -> 0.46153846 | P16: =$L$16*$N$16*2/($L$16+$N$16) -> 0.57142857 | Q16: =($B$16-$C$16-$E$16)/$B$16 -> 0.53333333 | R16: =($B$16-$D$16-$F$16)/$B$16 -> 0.6 | T16: LLM - qwen | U16: =S56 -> 0.75126904 | V16: =T56 -> 0.66326531 | W16: =U56 -> 0.6974359 | X16: =V56 -> 0.68246445 | Y16: =W56 -> 0.77927928 | Z16: =X56 -> 0.7027027 | AA16: =Y56 -> 0.73423423 | AB16: =Z56 -> 0.6981982
A17: sklearn | B17: 30 | C17: =Final_evaluation!$H$228 -> 2 | D17: =Final_evaluation!$I$228 -> 1 | E17: =Final_evaluation!$H$229 -> 6 | F17: =Final_evaluation!$I$229 -> 4 | G17: =C17/B17 -> 0.066666667 | H17: =D17/B17 -> 0.033333333 | I17: =E17/B17 -> 0.2 | J17: =F17/B17 -> 0.13333333 | K17: =($B$17/2-$E$17)/(($B$17/2-$E$17)+$C$17) -> 0.81818182 | L17: =($B$17/2-$F$17)/(($B$17/2-$F$17)+$D$17) -> 0.91666667 | M17: =($B$17/2-$E$17)/($B$17/2) -> 0.6 | N17: =($B$17/2-$F$17)/($B$17/2) -> 0.73333333 | O17: =$K$17*$M$17*2/($K$17+$M$17) -> 0.69230769 | P17: =$L$17*$N$17*2/($L$17+$N$17) -> 0.81481481 | Q17: =($B$17-$C$17-$E$17)/$B$17 -> 0.73333333 | R17: =($B$17-$D$17-$F$17)/$B$17 -> 0.83333333 | T17: LLM - gpt5 | U17: =S67 -> 0.80365297 | V17: =T67 -> 0.80930233 | W17: =U67 -> 0.75829384 | X17: =V67 -> 0.81981982 | Y17: =W67 -> 0.80630631 | Z17: =X67 -> 0.81531532 | AA17: =Y67 -> 0.77027027 | AB17: =Z67 -> 0.81981982
A18: pandas | B18: 30 | C18: =Final_evaluation!$H$230 -> 5 | D18: =Final_evaluation!$I$230 -> 2 | E18: =Final_evaluation!$H$231 -> 5 | F18: =Final_evaluation!$I$231 -> 5 | G18: =C18/B18 -> 0.16666667 | H18: =D18/B18 -> 0.066666667 | I18: =E18/B18 -> 0.16666667 | J18: =F18/B18 -> 0.16666667 | K18: =($B$18/2-$E$18)/(($B$18/2-$E$18)+$C$18) -> 0.66666667 | L18: =($B$18/2-$F$18)/(($B$18/2-$F$18)+$D$18) -> 0.83333333 | M18: =($B$18/2-$E$18)/($B$18/2) -> 0.66666667 | N18: =($B$18/2-$F$18)/($B$18/2) -> 0.66666667 | O18: =$K$18*$M$18*2/($K$18+$M$18) -> 0.66666667 | P18: =$L$18*$N$18*2/($L$18+$N$18) -> 0.74074074 | Q18: =($B$18-$C$18-$E$18)/$B$18 -> 0.66666667 | R18: =($B$18-$D$18-$F$18)/$B$18 -> 0.76666667
A19: numpy | B19: 30 | C19: =Final_evaluation!$H$232 -> 5 | D19: =Final_evaluation!$I$232 -> 2 | E19: =Final_evaluation!$H$233 -> 8 | F19: =Final_evaluation!$I$233 -> 8 | G19: =C19/B19 -> 0.16666667 | H19: =D19/B19 -> 0.066666667 | I19: =E19/B19 -> 0.26666667 | J19: =F19/B19 -> 0.26666667 | K19: =($B$19/2-$E$19)/(($B$19/2-$E$19)+$C$19) -> 0.58333333 | L19: =($B$19/2-$F$19)/(($B$19/2-$F$19)+$D$19) -> 0.77777778 | M19: =($B$19/2-$E$19)/($B$19/2) -> 0.46666667 | N19: =($B$19/2-$F$19)/($B$19/2) -> 0.46666667 | O19: =$K$19*$M$19*2/($K$19+$M$19) -> 0.51851852 | P19: =$L$19*$N$19*2/($L$19+$N$19) -> 0.58333333 | Q19: =($B$19-$C$19-$E$19)/$B$19 -> 0.56666667 | R19: =($B$19-$D$19-$F$19)/$B$19 -> 0.66666667 | T19: Diff | V19: F1+RT-S | W19: F1+RT-V | X19: F1+RT-R | Y19: Acc+RT | Z19: Acc+RT-S | AA19: Acc+RT-V | AB19: Acc+RT-R
A20: other | B20: 32 | C20: =Final_evaluation!$H$234 -> 4 | D20: =Final_evaluation!$I$234 -> 2 | E20: =Final_evaluation!$H$235 -> 9 | F20: =Final_evaluation!$I$235 -> 9 | G20: =C20/B20 -> 0.125 | H20: =D20/B20 -> 0.0625 | I20: =E20/B20 -> 0.28125 | J20: =F20/B20 -> 0.28125 | K20: =($B$20/2-$E$20)/(($B$20/2-$E$20)+$C$20) -> 0.63636364 | L20: =($B$20/2-$F$20)/(($B$20/2-$F$20)+$D$20) -> 0.77777778 | M20: =($B$20/2-$E$20)/($B$20/2) -> 0.4375 | N20: =($B$20/2-$F$20)/($B$20/2) -> 0.4375 | O20: =$K$20*$M$20*2/($K$20+$M$20) -> 0.51851852 | P20: =$L$20*$N$20*2/($L$20+$N$20) -> 0.56 | Q20: =($B$20-$C$20-$E$20)/$B$20 -> 0.59375 | R20: =($B$20-$D$20-$F$20)/$B$20 -> 0.65625 | T20: LLM - gemini | V20: =V15-U15 -> 0.002480351 | W20: =W15-U15 -> -0.0030810768 | X20: =X15-U15 -> -0.012615516 | Z20: =Z15-Y15 -> 0.009009009 | AA20: =AA15-Y15 -> 0.009009009 | AB20: =AB15-Y15 -> -0.013513514
A21: NBspecific | B21: 40 | C21: =Final_evaluation!$H$236 -> 1 | D21: =Final_evaluation!$I$236 -> 0 | E21: =Final_evaluation!$H$237 -> 0 | F21: =Final_evaluation!$I$237 -> 2 | G21: =C21/B21 -> 0.025 | H21: =D21/B21 -> 0 | I21: =E21/B21 -> 0 | J21: =F21/B21 -> 0.05 | K21: =($B$21/2-$E$21)/(($B$21/2-$E$21)+$C$21) -> 0.95238095 | L21: =($B$21/2-$F$21)/(($B$21/2-$F$21)+$D$21) -> 1 | M21: =($B$21/2-$E$21)/($B$21/2) -> 1 | N21: =($B$21/2-$F$21)/($B$21/2) -> 0.9 | O21: =$K$21*$M$21*2/($K$21+$M$21) -> 0.97560976 | P21: =$L$21*$N$21*2/($L$21+$N$21) -> 0.94736842 | Q21: =($B$21-$C$21-$E$21)/$B$21 -> 0.975 | R21: =($B$21-$D$21-$F$21)/$B$21 -> 0.95 | T21: LLM - qwen | V21: =V16-U16 -> -0.088003729 | W21: =W16-U16 -> -0.053833138 | X21: =X16-U16 -> -0.068804581 | Z21: =Z16-Y16 -> -0.076576577 | AA21: =AA16-Y16 -> -0.045045045 | AB21: =AB16-Y16 -> -0.081081081
A22: total | B22: =SUM(B15:B21) -> 222 | C22: =SUM(C15:C21) -> 27 | D22: =SUM(D15:D21) -> 12 | E22: =SUM(E15:E21) -> 40 | F22: =SUM(F15:F21) -> 37 | G22: =C22/B22 -> 0.12162162 | H22: =D22/B22 -> 0.054054054 | I22: =E22/B22 -> 0.18018018 | J22: =F22/B22 -> 0.16666667 | K22: =($B$22/2-$E$22)/(($B$22/2-$E$22)+$C$22) -> 0.7244898 | L22: =($B$22/2-$F$22)/(($B$22/2-$F$22)+$D$22) -> 0.86046512 | M22: =($B$22/2-$E$22)/($B$22/2) -> 0.63963964 | N22: =($B$22/2-$F$22)/($B$22/2) -> 0.66666667 | O22: =$K$22*$M$22*2/($K$22+$M$22) -> 0.67942584 | P22: =$L$22*$N$22*2/($L$22+$N$22) -> 0.75126904 | Q22: =($B$22-$C$22-$E$22)/$B$22 -> 0.6981982 | R22: =($B$22-$D$22-$F$22)/$B$22 -> 0.77927928 | T22: LLM - gpt5 | V22: =V17-U17 -> 0.0056493575 | W22: =W17-U17 -> -0.045359129 | X22: =X17-U17 -> 0.016166852 | Z22: =Z17-Y17 -> 0.009009009 | AA22: =AA17-Y17 -> -0.036036036 | AB22: =AB17-Y17 -> 0.013513514
T24: LLM | U24: Runtime information with documentation | Z24: Additional input tokens introduced by API documentation
A25: gpt 5 | B25: Count | C25: FP-RT | D25: FP+RT | E25: FN-RT | F25: FN+RT | G25: FPR-RT | H25: FPR+RT | I25: FNR-RT | J25: FNR+RT | K25: Prec-RT | L25: Prec+RT | M25: Rec-RT | N25: Rec+RT | O25: F1-RT | P25: F1+RT | Q25: Acc-RT | R25: Acc+RT | U25: F1+RT | V25: F1+RT+doc | W25: Acc+RT | X25: Acc+RT+doc | Z25: Statistics | AA25: Mean | AB25: Median | AC25: 75th | AD25: 90th
A26: tensorflow | B26: 30 | C26: =Final_evaluation!$N$224 -> 3 | D26: =Final_evaluation!$O$224 -> 2 | E26: =Final_evaluation!$N$225 -> 2 | F26: =Final_evaluation!$O$225 -> 3 | G26: =C26/B26 -> 0.1 | H26: =D26/B26 -> 0.066666667 | I26: =E26/B26 -> 0.066666667 | J26: =F26/B26 -> 0.1 | K26: =($B$26/2-$E$26)/(($B$26/2-$E$26)+$C$26) -> 0.8125 | L26: =($B$26/2-$F$26)/(($B$26/2-$F$26)+$D$26) -> 0.85714286 | M26: =($B$26/2-$E$26)/($B$26/2) -> 0.86666667 | N26: =($B$26/2-$F$26)/($B$26/2) -> 0.8 | O26: =$K$26*$M$26*2/($K$26+$M$26) -> 0.83870968 | P26: =$L$26*$N$26*2/($L$26+$N$26) -> 0.82758621 | Q26: =($B$26-$C$26-$E$26)/$B$26 -> 0.83333333 | R26: =($B$26-$D$26-$F$26)/$B$26 -> 0.83333333 | T26: LLM - gemini | U26: =K79 -> 0.77042802 | V26: =L79 -> 0.75697211 | W26: =M79 -> 0.73423423 | X26: =N79 -> 0.72522523 | Z26: Tokens | AA26: 855 | AB26: 569 | AC26: 1198 | AD26: 2386
A27: torch | B27: 30 | C27: =Final_evaluation!$N$226 -> 3 | D27: =Final_evaluation!$O$226 -> 5 | E27: =Final_evaluation!$N$227 -> 5 | F27: =Final_evaluation!$O$227 -> 3 | G27: =C27/B27 -> 0.1 | H27: =D27/B27 -> 0.16666667 | I27: =E27/B27 -> 0.16666667 | J27: =F27/B27 -> 0.1 | K27: =($B$27/2-$E$27)/(($B$27/2-$E$27)+$C$27) -> 0.76923077 | L27: =($B$27/2-$F$27)/(($B$27/2-$F$27)+$D$27) -> 0.70588235 | M27: =($B$27/2-$E$27)/($B$27/2) -> 0.66666667 | N27: =($B$27/2-$F$27)/($B$27/2) -> 0.8 | O27: =$K$27*$M$27*2/($K$27+$M$27) -> 0.71428571 | P27: =$L$27*$N$27*2/($L$27+$N$27) -> 0.75 | Q27: =($B$27-$C$27-$E$27)/$B$27 -> 0.73333333 | R27: =($B$27-$D$27-$F$27)/$B$27 -> 0.73333333 | T27: LLM - qwen | U27: =K90 -> 0.75126904 | V27: =L90 -> 0.71134021 | W27: =M90 -> 0.77927928 | X27: =N90 -> 0.74774775 | Z27: Increase over baseline | AA27: 0.736 | AB27: 0.359 | AC27: 0.938 | AD27: 1.981
A28: sklearn | B28: 30 | C28: =Final_evaluation!$N$228 -> 2 | D28: =Final_evaluation!$O$228 -> 3 | E28: =Final_evaluation!$N$229 -> 3 | F28: =Final_evaluation!$O$229 -> 1 | G28: =C28/B28 -> 0.066666667 | H28: =D28/B28 -> 0.1 | I28: =E28/B28 -> 0.1 | J28: =F28/B28 -> 0.033333333 | K28: =($B$28/2-$E$28)/(($B$28/2-$E$28)+$C$28) -> 0.85714286 | L28: =($B$28/2-$F$28)/(($B$28/2-$F$28)+$D$28) -> 0.82352941 | M28: =($B$28/2-$E$28)/($B$28/2) -> 0.8 | N28: =($B$28/2-$F$28)/($B$28/2) -> 0.93333333 | O28: =$K$28*$M$28*2/($K$28+$M$28) -> 0.82758621 | P28: =$L$28*$N$28*2/($L$28+$N$28) -> 0.875 | Q28: =($B$28-$C$28-$E$28)/$B$28 -> 0.83333333 | R28: =($B$28-$D$28-$F$28)/$B$28 -> 0.86666667 | T28: LLM - gpt5 | U28: =K101 -> 0.80365297 | V28: =L101 -> 0.79262673 | W28: =M101 -> 0.80630631 | X28: =N101 -> 0.7972973
A29: pandas | B29: 30 | C29: =Final_evaluation!$N$230 -> 5 | D29: =Final_evaluation!$O$230 -> 2 | E29: =Final_evaluation!$N$231 -> 8 | F29: =Final_evaluation!$O$231 -> 5 | G29: =C29/B29 -> 0.16666667 | H29: =D29/B29 -> 0.066666667 | I29: =E29/B29 -> 0.26666667 | J29: =F29/B29 -> 0.16666667 | K29: =($B$29/2-$E$29)/(($B$29/2-$E$29)+$C$29) -> 0.58333333 | L29: =($B$29/2-$F$29)/(($B$29/2-$F$29)+$D$29) -> 0.83333333 | M29: =($B$29/2-$E$29)/($B$29/2) -> 0.46666667 | N29: =($B$29/2-$F$29)/($B$29/2) -> 0.66666667 | O29: =$K$29*$M$29*2/($K$29+$M$29) -> 0.51851852 | P29: =$L$29*$N$29*2/($L$29+$N$29) -> 0.74074074 | Q29: =($B$29-$C$29-$E$29)/$B$29 -> 0.56666667 | R29: =($B$29-$D$29-$F$29)/$B$29 -> 0.76666667
A30: numpy | B30: 30 | C30: =Final_evaluation!$N$232 -> 4 | D30: =Final_evaluation!$O$232 -> 3 | E30: =Final_evaluation!$N$233 -> 4 | F30: =Final_evaluation!$O$233 -> 4 | G30: =C30/B30 -> 0.13333333 | H30: =D30/B30 -> 0.1 | I30: =E30/B30 -> 0.13333333 | J30: =F30/B30 -> 0.13333333 | K30: =($B$30/2-$E$30)/(($B$30/2-$E$30)+$C$30) -> 0.73333333 | L30: =($B$30/2-$F$30)/(($B$30/2-$F$30)+$D$30) -> 0.78571429 | M30: =($B$30/2-$E$30)/($B$30/2) -> 0.73333333 | N30: =($B$30/2-$F$30)/($B$30/2) -> 0.73333333 | O30: =$K$30*$M$30*2/($K$30+$M$30) -> 0.73333333 | P30: =$L$30*$N$30*2/($L$30+$N$30) -> 0.75862069 | Q30: =($B$30-$C$30-$E$30)/$B$30 -> 0.73333333 | R30: =($B$30-$D$30-$F$30)/$B$30 -> 0.76666667
